Workbook

Sheet Aulas
B1: Aula 1 | C1: Aula 2 | D1: Aula 3 | E1: Aula 4 | F1: Aula 5 | G1: Aula 6 | H1: Aula 7 | I1: Aula 8 | J1: Aula 9 | K1: Lab
A2: Lunes
A3: 1ro
A4: 2do | C4: =SUSTITUIR(ESPACIOS(CONCATENAR(SI(C111!$C$5=C$2;C111!$B$1 & " "; "")SI(C121!$C$5=C$2;C121!$B$1 & " "; "")SI(C122!$C$5=C$2;C122!$B$1 & " "; "")SI(C211!$C$5=C$2;C211!$B$1 & " "; "")SI(C212!$C$5=C$2;C212!$B$1 & " "; "")SI(C311!$C$5=C$2;C311!$B$1 & " "; "")SI(C312!$C$5=C$2;C312!$B$1 & " "; "")SI(C411!$C$5=C$2;C411!$B$1 & " "; "")SI(C412!$C$5=C$2;C412!$B$1 & " "; "")SI(D111!$C$5=C$2;D111!$B$1 & " "; "")SI(D211!$C$5=C$2;D211!$B$1 & " "; "")SI(D311!$C$5=C$2;D311!$B$1 & " "; "")SI(D411!$C$5=C$2;D411!$B$1 & " "; "")SI(M111!$C$5=C$2;M111!$B$1 & " "; "")SI(M211!$C$5=C$2;M211!$B$1 & " "; "")SI(M311!$C$5=C$2;M311!$B$1 & " "; "")SI(M411!$C$5=C$2;M411!$B$1 & " "; ""))); " "; ",") | D4: =SUSTITUIR(ESPACIOS(CONCATENAR(SI(C111!$C$5=D$2;C111!$B$1 & " "; "")SI(C121!$C$5=D$2;C121!$B$1 & " "; "")SI(C122!$C$5=D$2;C122!$B$1 & " "; "")SI(C211!$C$5=D$2;C211!$B$1 & " "; "")SI(C212!$C$5=D$2;C212!$B$1 & " "; "")SI(C311!$C$5=D$2;C311!$B$1 & " "; "")SI(C312!$C$5=D$2;C312!$B$1 & " "; "")SI(C411!$C$5=D$2;C411!$B$1 & " "; "")SI(C412!$C$5=D$2;C412!$B$1 & " "; "")SI(D111!$C$5=D$2;D111!$B$1 & " "; "")SI(D211!$C$5=D$2;D211!$B$1 & " "; "")SI(D311!$C$5=D$2;D311!$B$1 & " "; "")SI(D411!$C$5=D$2;D411!$B$1 & " "; "")SI(M111!$C$5=D$2;M111!$B$1 & " "; "")SI(M211!$C$5=D$2;M211!$B$1 & " "; "")SI(M311!$C$5=D$2;M311!$B$1 & " "; "")SI(M411!$C$5=D$2;M411!$B$1 & " "; ""))); " "; ",") | E4: =SUSTITUIR(ESPACIOS(CONCATENAR(SI(C111!$C$5=E$2;C111!$B$1 & " "; "")SI(C121!$C$5=E$2;C121!$B$1 & " "; "")SI(C122!$C$5=E$2;C122!$B$1 & " "; "")SI(C211!$C$5=E$2;C211!$B$1 & " "; "")SI(C212!$C$5=E$2;C212!$B$1 & " "; "")SI(C311!$C$5=E$2;C311!$B$1 & " "; "")SI(C312!$C$5=E$2;C312!$B$1 & " "; "")SI(C411!$C$5=E$2;C411!$B$1 & " "; "")SI(C412!$C$5=E$2;C412!$B$1 & " "; "")SI(D111!$C$5=E$2;D111!$B$1 & " "; "")SI(D211!$C$5=E$2;D211!$B$1 & " "; "")SI(D311!$C$5=E$2;D311!$B$1 & " "; "")SI(D411!$C$5=E$2;D411!$B$1 & " "; "")SI(M111!$C$5=E$2;M111!$B$1 & " "; "")SI(M211!$C$5=E$2;M211!$B$1 & " "; "")SI(M311!$C$5=E$2;M311!$B$1 & " "; "")SI(M411!$C$5=E$2;M411!$B$1 & " "; ""))); " "; ",") | F4: =SUSTITUIR(ESPACIOS(CONCATENAR(SI(C111!$C$5=F$2;C111!$B$1 & " "; "")SI(C121!$C$5=F$2;C121!$B$1 & " "; "")SI(C122!$C$5=F$2;C122!$B$1 & " "; "")SI(C211!$C$5=F$2;C211!$B$1 & " "; "")SI(C212!$C$5=F$2;C212!$B$1 & " "; "")SI(C311!$C$5=F$2;C311!$B$1 & " "; "")SI(C312!$C$5=F$2;C312!$B$1 & " "; "")SI(C411!$C$5=F$2;C411!$B$1 & " "; "")SI(C412!$C$5=F$2;C412!$B$1 & " "; "")SI(D111!$C$5=F$2;D111!$B$1 & " "; "")SI(D211!$C$5=F$2;D211!$B$1 & " "; "")SI(D311!$C$5=F$2;D311!$B$1 & " "; "")SI(D411!$C$5=F$2;D411!$B$1 & " "; "")SI(M111!$C$5=F$2;M111!$B$1 & " "; "")SI(M211!$C$5=F$2;M211!$B$1 & " "; "")SI(M311!$C$5=F$2;M311!$B$1 & " "; "")SI(M411!$C$5=F$2;M411!$B$1 & " "; ""))); " "; ",") | G4: =SUSTITUIR(ESPACIOS(CONCATENAR(SI(C111!$C$5=G$2;C111!$B$1 & " "; "")SI(C121!$C$5=G$2;C121!$B$1 & " "; "")SI(C122!$C$5=G$2;C122!$B$1 & " "; "")SI(C211!$C$5=G$2;C211!$B$1 & " "; "")SI(C212!$C$5=G$2;C212!$B$1 & " "; "")SI(C311!$C$5=G$2;C311!$B$1 & " "; "")SI(C312!$C$5=G$2;C312!$B$1 & " "; "")SI(C411!$C$5=G$2;C411!$B$1 & " "; "")SI(C412!$C$5=G$2;C412!$B$1 & " "; "")SI(D111!$C$5=G$2;D111!$B$1 & " "; "")SI(D211!$C$5=G$2;D211!$B$1 & " "; "")SI(D311!$C$5=G$2;D311!$B$1 & " "; "")SI(D411!$C$5=G$2;D411!$B$1 & " "; "")SI(M111!$C$5=G$2;M111!$B$1 & " "; "")SI(M211!$C$5=G$2;M211!$B$1 & " "; "")SI(M311!$C$5=G$2;M311!$B$1 & " "; "")SI(M411!$C$5=G$2;M411!$B$1 & " "; ""))); " "; ",") | H4: =SUSTITUIR(ESPACIOS(CONCATENAR(SI(C111!$C$5=H$2;C111!$B$1 & " "; "")SI(C121!$C$5=H$2;C121!$B$1 & " "; "")SI(C122!$C$5=H$2;C122!$B$1 & " "; "")SI(C211!$C$5=H$2;C211!$B$1 & " "; "")SI(C212!$C$5=H$2;C212!$B$1 & " "; "")SI(C311!$C$5=H$2;C311!$B$1 & " "; "")SI(C312!$C$5=H$2;C312!$B$1 & " "; "")SI(C411!$C$5=H$2;C411!$B$1 & " "; "")SI(C412!$C$5=H$2;C412!$B$1 & " "; "")SI(D111!$C$5=H$2;D111!$B$1 & " "; "")SI(D211!$C$5=H$2;D211!$B$1 & " "; "")SI(D311!$C$5=H$2;D311!$B$1 & " "; "")SI(D411!$C$5=H$2;D411!$B$1 & " "; "")SI(M111!$C$5=H$2;M111!$B$1 & " "; "")SI(M211!$C$5=H$2;M211!$B$1 & " "; "")SI(M311!$C$5=H$2;M311!$B$1 & " "; "")SI(M411!$C$5=H$2;M411!$B$1 & " "; ""))); " "; ",") | I4: =SUSTITUIR(ESPACIOS(CONCATENAR(SI(C111!$C$5=I$2;C111!$B$1 & " "; "")SI(C121!$C$5=I$2;C121!$B$1 & " "; "")SI(C122!$C$5=I$2;C122!$B$1 & " "; "")SI(C211!$C$5=I$2;C211!$B$1 & " "; "")SI(C212!$C$5=I$2;C212!$B$1 & " "; "")SI(C311!$C$5=I$2;C311!$B$1 & " "; "")SI(C312!$C$5=I$2;C312!$B$1 & " "; "")SI(C411!$C$5=I$2;C411!$B$1 & " "; "")SI(C412!$C$5=I$2;C412!$B$1 & " "; "")SI(D111!$C$5=I$2;D111!$B$1 & " "; "")SI(D211!$C$5=I$2;D211!$B$1 & " "; "")SI(D311!$C$5=I$2;D311!$B$1 & " "; "")SI(D411!$C$5=I$2;D411!$B$1 & " "; "")SI(M111!$C$5=I$2;M111!$B$1 & " "; "")SI(M211!$C$5=I$2;M211!$B$1 & " "; "")SI(M311!$C$5=I$2;M311!$B$1 & " "; "")SI(M411!$C$5=I$2;M411!$B$1 & " "; ""))); " "; ",") | J4: =SUSTITUIR(ESPACIOS(CONCATENAR(SI(C111!$C$5=J$2;C111!$B$1 & " "; "")SI(C121!$C$5=J$2;C121!$B$1 & " "; "")SI(C122!$C$5=J$2;C122!$B$1 & " "; "")SI(C211!$C$5=J$2;C211!$B$1 & " "; "")SI(C212!$C$5=J$2;C212!$B$1 & " "; "")SI(C311!$C$5=J$2;C311!$B$1 & " "; "")SI(C312!$C$5=J$2;C312!$B$1 & " "; "")SI(C411!$C$5=J$2;C411!$B$1 & " "; "")SI(C412!$C$5=J$2;C412!$B$1 & " "; "")SI(D111!$C$5=J$2;D111!$B$1 & " "; "")SI(D211!$C$5=J$2;D211!$B$1 & " "; "")SI(D311!$C$5=J$2;D311!$B$1 & " "; "")SI(D411!$C$5=J$2;D411!$B$1 & " "; "")SI(M111!$C$5=J$2;M111!$B$1 & " "; "")SI(M211!$C$5=J$2;M211!$B$1 & " "; "")SI(M311!$C$5=J$2;M311!$B$1 & " "; "")SI(M411!$C$5=J$2;M411!$B$1 & " "; ""))); " "; ",") | ... L4: =SUSTITUIR(ESPACIOS(CONCATENAR(SI(C111!$C$5=L$2;C111!$B$1 & " "; "")SI(C121!$C$5=L$2;C121!$B$1 & " "; "")SI(C122!$C$5=L$2;C122!$B$1 & " "; "")SI(C211!$C$5=L$2;C211!$B$1 & " "; "")SI(C212!$C$5=L$2;C212!$B$1 & " "; "")SI(C311!$C$5=L$2;C311!$B$1 & " "; "")SI(C312!$C$5=L$2;C312!$B$1 & " "; "")SI(C411!$C$5=L$2;C411!$B$1 & " "; "")SI(C412!$C$5=L$2;C412!$B$1 & " "; "")SI(D111!$C$5=L$2;D111!$B$1 & " "; "")SI(D211!$C$5=L$2;D211!$B$1 & " "; "")SI(D311!$C$5=L$2;D311!$B$1 & " "; "")SI(D411!$C$5=L$2;D411!$B$1 & " "; "")SI(M111!$C$5=L$2;M111!$B$1 & " "; "")SI(M211!$C$5=L$2;M211!$B$1 & " "; "")SI(M311!$C$5=L$2;M311!$B$1 & " "; "")SI(M411!$C$5=L$2;M411!$B$1 & " "; ""))); " "; ",")
A5: 3ro | C5: =SUSTITUIR(ESPACIOS(CONCATENAR(SI(C111!$C$5=C$2;C111!$B$1 & " "; "")SI(C121!$C$5=C$2;C121!$B$1 & " "; "")SI(C122!$C$5=C$2;C122!$B$1 & " "; "")SI(C211!$C$5=C$2;C211!$B$1 & " "; "")SI(C212!$C$5=C$2;C212!$B$1 & " "; "")SI(C311!$C$5=C$2;C311!$B$1 & " "; "")SI(C312!$C$5=C$2;C312!$B$1 & " "; "")SI(C411!$C$5=C$2;C411!$B$1 & " "; "")SI(C412!$C$5=C$2;C412!$B$1 & " "; "")SI(D111!$C$5=C$2;D111!$B$1 & " "; "")SI(D211!$C$5=C$2;D211!$B$1 & " "; "")SI(D311!$C$5=C$2;D311!$B$1 & " "; "")SI(D411!$C$5=C$2;D411!$B$1 & " "; "")SI(M111!$C$5=C$2;M111!$B$1 & " "; "")SI(M211!$C$5=C$2;M211!$B$1 & " "; "")SI(M311!$C$5=C$2;M311!$B$1 & " "; "")SI(M411!$C$5=C$2;M411!$B$1 & " "; ""))); " "; ",") | D5: =SUSTITUIR(ESPACIOS(CONCATENAR(SI(C111!$C$5=D$2;C111!$B$1 & " "; "")SI(C121!$C$5=D$2;C121!$B$1 & " "; "")SI(C122!$C$5=D$2;C122!$B$1 & " "; "")SI(C211!$C$5=D$2;C211!$B$1 & " "; "")SI(C212!$C$5=D$2;C212!$B$1 & " "; "")SI(C311!$C$5=D$2;C311!$B$1 & " "; "")SI(C312!$C$5=D$2;C312!$B$1 & " "; "")SI(C411!$C$5=D$2;C411!$B$1 & " "; "")SI(C412!$C$5=D$2;C412!$B$1 & " "; "")SI(D111!$C$5=D$2;D111!$B$1 & " "; "")SI(D211!$C$5=D$2;D211!$B$1 & " "; "")SI(D311!$C$5=D$2;D311!$B$1 & " "; "")SI(D411!$C$5=D$2;D411!$B$1 & " "; "")SI(M111!$C$5=D$2;M111!$B$1 & " "; "")SI(M211!$C$5=D$2;M211!$B$1 & " "; "")SI(M311!$C$5=D$2;M311!$B$1 & " "; "")SI(M411!$C$5=D$2;M411!$B$1 & " "; ""))); " "; ",") | E5: =SUSTITUIR(ESPACIOS(CONCATENAR(SI(C111!$C$5=E$2;C111!$B$1 & " "; "")SI(C121!$C$5=E$2;C121!$B$1 & " "; "")SI(C122!$C$5=E$2;C122!$B$1 & " "; "")SI(C211!$C$5=E$2;C211!$B$1 & " "; "")SI(C212!$C$5=E$2;C212!$B$1 & " "; "")SI(C311!$C$5=E$2;C311!$B$1 & " "; "")SI(C312!$C$5=E$2;C312!$B$1 & " "; "")SI(C411!$C$5=E$2;C411!$B$1 & " "; "")SI(C412!$C$5=E$2;C412!$B$1 & " "; "")SI(D111!$C$5=E$2;D111!$B$1 & " "; "")SI(D211!$C$5=E$2;D211!$B$1 & " "; "")SI(D311!$C$5=E$2;D311!$B$1 & " "; "")SI(D411!$C$5=E$2;D411!$B$1 & " "; "")SI(M111!$C$5=E$2;M111!$B$1 & " "; "")SI(M211!$C$5=E$2;M211!$B$1 & " "; "")SI(M311!$C$5=E$2;M311!$B$1 & " "; "")SI(M411!$C$5=E$2;M411!$B$1 & " "; ""))); " "; ",") | F5: =SUSTITUIR(ESPACIOS(CONCATENAR(SI(C111!$C$5=F$2;C111!$B$1 & " "; "")SI(C121!$C$5=F$2;C121!$B$1 & " "; "")SI(C122!$C$5=F$2;C122!$B$1 & " "; "")SI(C211!$C$5=F$2;C211!$B$1 & " "; "")SI(C212!$C$5=F$2;C212!$B$1 & " "; "")SI(C311!$C$5=F$2;C311!$B$1 & " "; "")SI(C312!$C$5=F$2;C312!$B$1 & " "; "")SI(C411!$C$5=F$2;C411!$B$1 & " "; "")SI(C412!$C$5=F$2;C412!$B$1 & " "; "")SI(D111!$C$5=F$2;D111!$B$1 & " "; "")SI(D211!$C$5=F$2;D211!$B$1 & " "; "")SI(D311!$C$5=F$2;D311!$B$1 & " "; "")SI(D411!$C$5=F$2;D411!$B$1 & " "; "")SI(M111!$C$5=F$2;M111!$B$1 & " "; "")SI(M211!$C$5=F$2;M211!$B$1 & " "; "")SI(M311!$C$5=F$2;M311!$B$1 & " "; "")SI(M411!$C$5=F$2;M411!$B$1 & " "; ""))); " "; ",") | G5: =SUSTITUIR(ESPACIOS(CONCATENAR(SI(C111!$C$5=G$2;C111!$B$1 & " "; "")SI(C121!$C$5=G$2;C121!$B$1 & " "; "")SI(C122!$C$5=G$2;C122!$B$1 & " "; "")SI(C211!$C$5=G$2;C211!$B$1 & " "; "")SI(C212!$C$5=G$2;C212!$B$1 & " "; "")SI(C311!$C$5=G$2;C311!$B$1 & " "; "")SI(C312!$C$5=G$2;C312!$B$1 & " "; "")SI(C411!$C$5=G$2;C411!$B$1 & " "; "")SI(C412!$C$5=G$2;C412!$B$1 & " "; "")SI(D111!$C$5=G$2;D111!$B$1 & " "; "")SI(D211!$C$5=G$2;D211!$B$1 & " "; "")SI(D311!$C$5=G$2;D311!$B$1 & " "; "")SI(D411!$C$5=G$2;D411!$B$1 & " "; "")SI(M111!$C$5=G$2;M111!$B$1 & " "; "")SI(M211!$C$5=G$2;M211!$B$1 & " "; "")SI(M311!$C$5=G$2;M311!$B$1 & " "; "")SI(M411!$C$5=G$2;M411!$B$1 & " "; ""))); " "; ",") | H5: =SUSTITUIR(ESPACIOS(CONCATENAR(SI(C111!$C$5=H$2;C111!$B$1 & " "; "")SI(C121!$C$5=H$2;C121!$B$1 & " "; "")SI(C122!$C$5=H$2;C122!$B$1 & " "; "")SI(C211!$C$5=H$2;C211!$B$1 & " "; "")SI(C212!$C$5=H$2;C212!$B$1 & " "; "")SI(C311!$C$5=H$2;C311!$B$1 & " "; "")SI(C312!$C$5=H$2;C312!$B$1 & " "; "")SI(C411!$C$5=H$2;C411!$B$1 & " "; "")SI(C412!$C$5=H$2;C412!$B$1 & " "; "")SI(D111!$C$5=H$2;D111!$B$1 & " "; "")SI(D211!$C$5=H$2;D211!$B$1 & " "; "")SI(D311!$C$5=H$2;D311!$B$1 & " "; "")SI(D411!$C$5=H$2;D411!$B$1 & " "; "")SI(M111!$C$5=H$2;M111!$B$1 & " "; "")SI(M211!$C$5=H$2;M211!$B$1 & " "; "")SI(M311!$C$5=H$2;M311!$B$1 & " "; "")SI(M411!$C$5=H$2;M411!$B$1 & " "; ""))); " "; ",") | I5: =SUSTITUIR(ESPACIOS(CONCATENAR(SI(C111!$C$5=I$2;C111!$B$1 & " "; "")SI(C121!$C$5=I$2;C121!$B$1 & " "; "")SI(C122!$C$5=I$2;C122!$B$1 & " "; "")SI(C211!$C$5=I$2;C211!$B$1 & " "; "")SI(C212!$C$5=I$2;C212!$B$1 & " "; "")SI(C311!$C$5=I$2;C311!$B$1 & " "; "")SI(C312!$C$5=I$2;C312!$B$1 & " "; "")SI(C411!$C$5=I$2;C411!$B$1 & " "; "")SI(C412!$C$5=I$2;C412!$B$1 & " "; "")SI(D111!$C$5=I$2;D111!$B$1 & " "; "")SI(D211!$C$5=I$2;D211!$B$1 & " "; "")SI(D311!$C$5=I$2;D311!$B$1 & " "; "")SI(D411!$C$5=I$2;D411!$B$1 & " "; "")SI(M111!$C$5=I$2;M111!$B$1 & " "; "")SI(M211!$C$5=I$2;M211!$B$1 & " "; "")SI(M311!$C$5=I$2;M311!$B$1 & " "; "")SI(M411!$C$5=I$2;M411!$B$1 & " "; ""))); " "; ",") | J5: =SUSTITUIR(ESPACIOS(CONCATENAR(SI(C111!$C$5=J$2;C111!$B$1 & " "; "")SI(C121!$C$5=J$2;C121!$B$1 & " "; "")SI(C122!$C$5=J$2;C122!$B$1 & " "; "")SI(C211!$C$5=J$2;C211!$B$1 & " "; "")SI(C212!$C$5=J$2;C212!$B$1 & " "; "")SI(C311!$C$5=J$2;C311!$B$1 & " "; "")SI(C312!$C$5=J$2;C312!$B$1 & " "; "")SI(C411!$C$5=J$2;C411!$B$1 & " "; "")SI(C412!$C$5=J$2;C412!$B$1 & " "; "")SI(D111!$C$5=J$2;D111!$B$1 & " "; "")SI(D211!$C$5=J$2;D211!$B$1 & " "; "")SI(D311!$C$5=J$2;D311!$B$1 & " "; "")SI(D411!$C$5=J$2;D411!$B$1 & " "; "")SI(M111!$C$5=J$2;M111!$B$1 & " "; "")SI(M211!$C$5=J$2;M211!$B$1 & " "; "")SI(M311!$C$5=J$2;M311!$B$1 & " "; "")SI(M411!$C$5=J$2;M411!$B$1 & " "; ""))); " "; ",") | ... L5: =SUSTITUIR(ESPACIOS(CONCATENAR(SI(C111!$C$5=L$2;C111!$B$1 & " "; "")SI(C121!$C$5=L$2;C121!$B$1 & " "; "")SI(C122!$C$5=L$2;C122!$B$1 & " "; "")SI(C211!$C$5=L$2;C211!$B$1 & " "; "")SI(C212!$C$5=L$2;C212!$B$1 & " "; "")SI(C311!$C$5=L$2;C311!$B$1 & " "; "")SI(C312!$C$5=L$2;C312!$B$1 & " "; "")SI(C411!$C$5=L$2;C411!$B$1 & " "; "")SI(C412!$C$5=L$2;C412!$B$1 & " "; "")SI(D111!$C$5=L$2;D111!$B$1 & " "; "")SI(D211!$C$5=L$2;D211!$B$1 & " "; "")SI(D311!$C$5=L$2;D311!$B$1 & " "; "")SI(D411!$C$5=L$2;D411!$B$1 & " "; "")SI(M111!$C$5=L$2;M111!$B$1 & " "; "")SI(M211!$C$5=L$2;M211!$B$1 & " "; "")SI(M311!$C$5=L$2;M311!$B$1 & " "; "")SI(M411!$C$5=L$2;M411!$B$1 & " "; ""))); " "; ",")
A6: 4to | C6: =SUSTITUIR(ESPACIOS(CONCATENAR(SI(C111!$C$5=C$2;C111!$B$1 & " "; "")SI(C121!$C$5=C$2;C121!$B$1 & " "; "")SI(C122!$C$5=C$2;C122!$B$1 & " "; "")SI(C211!$C$5=C$2;C211!$B$1 & " "; "")SI(C212!$C$5=C$2;C212!$B$1 & " "; "")SI(C311!$C$5=C$2;C311!$B$1 & " "; "")SI(C312!$C$5=C$2;C312!$B$1 & " "; "")SI(C411!$C$5=C$2;C411!$B$1 & " "; "")SI(C412!$C$5=C$2;C412!$B$1 & " "; "")SI(D111!$C$5=C$2;D111!$B$1 & " "; "")SI(D211!$C$5=C$2;D211!$B$1 & " "; "")SI(D311!$C$5=C$2;D311!$B$1 & " "; "")SI(D411!$C$5=C$2;D411!$B$1 & " "; "")SI(M111!$C$5=C$2;M111!$B$1 & " "; "")SI(M211!$C$5=C$2;M211!$B$1 & " "; "")SI(M311!$C$5=C$2;M311!$B$1 & " "; "")SI(M411!$C$5=C$2;M411!$B$1 & " "; ""))); " "; ",") | D6: =SUSTITUIR(ESPACIOS(CONCATENAR(SI(C111!$C$5=D$2;C111!$B$1 & " "; "")SI(C121!$C$5=D$2;C121!$B$1 & " "; "")SI(C122!$C$5=D$2;C122!$B$1 & " "; "")SI(C211!$C$5=D$2;C211!$B$1 & " "; "")SI(C212!$C$5=D$2;C212!$B$1 & " "; "")SI(C311!$C$5=D$2;C311!$B$1 & " "; "")SI(C312!$C$5=D$2;C312!$B$1 & " "; "")SI(C411!$C$5=D$2;C411!$B$1 & " "; "")SI(C412!$C$5=D$2;C412!$B$1 & " "; "")SI(D111!$C$5=D$2;D111!$B$1 & " "; "")SI(D211!$C$5=D$2;D211!$B$1 & " "; "")SI(D311!$C$5=D$2;D311!$B$1 & " "; "")SI(D411!$C$5=D$2;D411!$B$1 & " "; "")SI(M111!$C$5=D$2;M111!$B$1 & " "; "")SI(M211!$C$5=D$2;M211!$B$1 & " "; "")SI(M311!$C$5=D$2;M311!$B$1 & " "; "")SI(M411!$C$5=D$2;M411!$B$1 & " "; ""))); " "; ",") | E6: =SUSTITUIR(ESPACIOS(CONCATENAR(SI(C111!$C$5=E$2;C111!$B$1 & " "; "")SI(C121!$C$5=E$2;C121!$B$1 & " "; "")SI(C122!$C$5=E$2;C122!$B$1 & " "; "")SI(C211!$C$5=E$2;C211!$B$1 & " "; "")SI(C212!$C$5=E$2;C212!$B$1 & " "; "")SI(C311!$C$5=E$2;C311!$B$1 & " "; "")SI(C312!$C$5=E$2;C312!$B$1 & " "; "")SI(C411!$C$5=E$2;C411!$B$1 & " "; "")SI(C412!$C$5=E$2;C412!$B$1 & " "; "")SI(D111!$C$5=E$2;D111!$B$1 & " "; "")SI(D211!$C$5=E$2;D211!$B$1 & " "; "")SI(D311!$C$5=E$2;D311!$B$1 & " "; "")SI(D411!$C$5=E$2;D411!$B$1 & " "; "")SI(M111!$C$5=E$2;M111!$B$1 & " "; "")SI(M211!$C$5=E$2;M211!$B$1 & " "; "")SI(M311!$C$5=E$2;M311!$B$1 & " "; "")SI(M411!$C$5=E$2;M411!$B$1 & " "; ""))); " "; ",") | F6: =SUSTITUIR(ESPACIOS(CONCATENAR(SI(C111!$C$5=F$2;C111!$B$1 & " "; "")SI(C121!$C$5=F$2;C121!$B$1 & " "; "")SI(C122!$C$5=F$2;C122!$B$1 & " "; "")SI(C211!$C$5=F$2;C211!$B$1 & " "; "")SI(C212!$C$5=F$2;C212!$B$1 & " "; "")SI(C311!$C$5=F$2;C311!$B$1 & " "; "")SI(C312!$C$5=F$2;C312!$B$1 & " "; "")SI(C411!$C$5=F$2;C411!$B$1 & " "; "")SI(C412!$C$5=F$2;C412!$B$1 & " "; "")SI(D111!$C$5=F$2;D111!$B$1 & " "; "")SI(D211!$C$5=F$2;D211!$B$1 & " "; "")SI(D311!$C$5=F$2;D311!$B$1 & " "; "")SI(D411!$C$5=F$2;D411!$B$1 & " "; "")SI(M111!$C$5=F$2;M111!$B$1 & " "; "")SI(M211!$C$5=F$2;M211!$B$1 & " "; "")SI(M311!$C$5=F$2;M311!$B$1 & " "; "")SI(M411!$C$5=F$2;M411!$B$1 & " "; ""))); " "; ",") | G6: =SUSTITUIR(ESPACIOS(CONCATENAR(SI(C111!$C$5=G$2;C111!$B$1 & " "; "")SI(C121!$C$5=G$2;C121!$B$1 & " "; "")SI(C122!$C$5=G$2;C122!$B$1 & " "; "")SI(C211!$C$5=G$2;C211!$B$1 & " "; "")SI(C212!$C$5=G$2;C212!$B$1 & " "; "")SI(C311!$C$5=G$2;C311!$B$1 & " "; "")SI(C312!$C$5=G$2;C312!$B$1 & " "; "")SI(C411!$C$5=G$2;C411!$B$1 & " "; "")SI(C412!$C$5=G$2;C412!$B$1 & " "; "")SI(D111!$C$5=G$2;D111!$B$1 & " "; "")SI(D211!$C$5=G$2;D211!$B$1 & " "; "")SI(D311!$C$5=G$2;D311!$B$1 & " "; "")SI(D411!$C$5=G$2;D411!$B$1 & " "; "")SI(M111!$C$5=G$2;M111!$B$1 & " "; "")SI(M211!$C$5=G$2;M211!$B$1 & " "; "")SI(M311!$C$5=G$2;M311!$B$1 & " "; "")SI(M411!$C$5=G$2;M411!$B$1 & " "; ""))); " "; ",") | H6: =SUSTITUIR(ESPACIOS(CONCATENAR(SI(C111!$C$5=H$2;C111!$B$1 & " "; "")SI(C121!$C$5=H$2;C121!$B$1 & " "; "")SI(C122!$C$5=H$2;C122!$B$1 & " "; "")SI(C211!$C$5=H$2;C211!$B$1 & " "; "")SI(C212!$C$5=H$2;C212!$B$1 & " "; "")SI(C311!$C$5=H$2;C311!$B$1 & " "; "")SI(C312!$C$5=H$2;C312!$B$1 & " "; "")SI(C411!$C$5=H$2;C411!$B$1 & " "; "")SI(C412!$C$5=H$2;C412!$B$1 & " "; "")SI(D111!$C$5=H$2;D111!$B$1 & " "; "")SI(D211!$C$5=H$2;D211!$B$1 & " "; "")SI(D311!$C$5=H$2;D311!$B$1 & " "; "")SI(D411!$C$5=H$2;D411!$B$1 & " "; "")SI(M111!$C$5=H$2;M111!$B$1 & " "; "")SI(M211!$C$5=H$2;M211!$B$1 & " "; "")SI(M311!$C$5=H$2;M311!$B$1 & " "; "")SI(M411!$C$5=H$2;M411!$B$1 & " "; ""))); " "; ",") | I6: =SUSTITUIR(ESPACIOS(CONCATENAR(SI(C111!$C$5=I$2;C111!$B$1 & " "; "")SI(C121!$C$5=I$2;C121!$B$1 & " "; "")SI(C122!$C$5=I$2;C122!$B$1 & " "; "")SI(C211!$C$5=I$2;C211!$B$1 & " "; "")SI(C212!$C$5=I$2;C212!$B$1 & " "; "")SI(C311!$C$5=I$2;C311!$B$1 & " "; "")SI(C312!$C$5=I$2;C312!$B$1 & " "; "")SI(C411!$C$5=I$2;C411!$B$1 & " "; "")SI(C412!$C$5=I$2;C412!$B$1 & " "; "")SI(D111!$C$5=I$2;D111!$B$1 & " "; "")SI(D211!$C$5=I$2;D211!$B$1 & " "; "")SI(D311!$C$5=I$2;D311!$B$1 & " "; "")SI(D411!$C$5=I$2;D411!$B$1 & " "; "")SI(M111!$C$5=I$2;M111!$B$1 & " "; "")SI(M211!$C$5=I$2;M211!$B$1 & " "; "")SI(M311!$C$5=I$2;M311!$B$1 & " "; "")SI(M411!$C$5=I$2;M411!$B$1 & " "; ""))); " "; ",") | J6: =SUSTITUIR(ESPACIOS(CONCATENAR(SI(C111!$C$5=J$2;C111!$B$1 & " "; "")SI(C121!$C$5=J$2;C121!$B$1 & " "; "")SI(C122!$C$5=J$2;C122!$B$1 & " "; "")SI(C211!$C$5=J$2;C211!$B$1 & " "; "")SI(C212!$C$5=J$2;C212!$B$1 & " "; "")SI(C311!$C$5=J$2;C311!$B$1 & " "; "")SI(C312!$C$5=J$2;C312!$B$1 & " "; "")SI(C411!$C$5=J$2;C411!$B$1 & " "; "")SI(C412!$C$5=J$2;C412!$B$1 & " "; "")SI(D111!$C$5=J$2;D111!$B$1 & " "; "")SI(D211!$C$5=J$2;D211!$B$1 & " "; "")SI(D311!$C$5=J$2;D311!$B$1 & " "; "")SI(D411!$C$5=J$2;D411!$B$1 & " "; "")SI(M111!$C$5=J$2;M111!$B$1 & " "; "")SI(M211!$C$5=J$2;M211!$B$1 & " "; "")SI(M311!$C$5=J$2;M311!$B$1 & " "; "")SI(M411!$C$5=J$2;M411!$B$1 & " "; ""))); " "; ",") | ... L6: =SUSTITUIR(ESPACIOS(CONCATENAR(SI(C111!$C$5=L$2;C111!$B$1 & " "; "")SI(C121!$C$5=L$2;C121!$B$1 & " "; "")SI(C122!$C$5=L$2;C122!$B$1 & " "; "")SI(C211!$C$5=L$2;C211!$B$1 & " "; "")SI(C212!$C$5=L$2;C212!$B$1 & " "; "")SI(C311!$C$5=L$2;C311!$B$1 & " "; "")SI(C312!$C$5=L$2;C312!$B$1 & " "; "")SI(C411!$C$5=L$2;C411!$B$1 & " "; "")SI(C412!$C$5=L$2;C412!$B$1 & " "; "")SI(D111!$C$5=L$2;D111!$B$1 & " "; "")SI(D211!$C$5=L$2;D211!$B$1 & " "; "")SI(D311!$C$5=L$2;D311!$B$1 & " "; "")SI(D411!$C$5=L$2;D411!$B$1 & " "; "")SI(M111!$C$5=L$2;M111!$B$1 & " "; "")SI(M211!$C$5=L$2;M211!$B$1 & " "; "")SI(M311!$C$5=L$2;M311!$B$1 & " "; "")SI(M411!$C$5=L$2;M411!$B$1 & " "; ""))); " "; ",")
A7: 5to | C7: =SUSTITUIR(ESPACIOS(CONCATENAR(SI(C111!$C$5=C$2;C111!$B$1 & " "; "")SI(C121!$C$5=C$2;C121!$B$1 & " "; "")SI(C122!$C$5=C$2;C122!$B$1 & " "; "")SI(C211!$C$5=C$2;C211!$B$1 & " "; "")SI(C212!$C$5=C$2;C212!$B$1 & " "; "")SI(C311!$C$5=C$2;C311!$B$1 & " "; "")SI(C312!$C$5=C$2;C312!$B$1 & " "; "")SI(C411!$C$5=C$2;C411!$B$1 & " "; "")SI(C412!$C$5=C$2;C412!$B$1 & " "; "")SI(D111!$C$5=C$2;D111!$B$1 & " "; "")SI(D211!$C$5=C$2;D211!$B$1 & " "; "")SI(D311!$C$5=C$2;D311!$B$1 & " "; "")SI(D411!$C$5=C$2;D411!$B$1 & " "; "")SI(M111!$C$5=C$2;M111!$B$1 & " "; "")SI(M211!$C$5=C$2;M211!$B$1 & " "; "")SI(M311!$C$5=C$2;M311!$B$1 & " "; "")SI(M411!$C$5=C$2;M411!$B$1 & " "; ""))); " "; ",") | D7: =SUSTITUIR(ESPACIOS(CONCATENAR(SI(C111!$C$5=D$2;C111!$B$1 & " "; "")SI(C121!$C$5=D$2;C121!$B$1 & " "; "")SI(C122!$C$5=D$2;C122!$B$1 & " "; "")SI(C211!$C$5=D$2;C211!$B$1 & " "; "")SI(C212!$C$5=D$2;C212!$B$1 & " "; "")SI(C311!$C$5=D$2;C311!$B$1 & " "; "")SI(C312!$C$5=D$2;C312!$B$1 & " "; "")SI(C411!$C$5=D$2;C411!$B$1 & " "; "")SI(C412!$C$5=D$2;C412!$B$1 & " "; "")SI(D111!$C$5=D$2;D111!$B$1 & " "; "")SI(D211!$C$5=D$2;D211!$B$1 & " "; "")SI(D311!$C$5=D$2;D311!$B$1 & " "; "")SI(D411!$C$5=D$2;D411!$B$1 & " "; "")SI(M111!$C$5=D$2;M111!$B$1 & " "; "")SI(M211!$C$5=D$2;M211!$B$1 & " "; "")SI(M311!$C$5=D$2;M311!$B$1 & " "; "")SI(M411!$C$5=D$2;M411!$B$1 & " "; ""))); " "; ",") | E7: =SUSTITUIR(ESPACIOS(CONCATENAR(SI(C111!$C$5=E$2;C111!$B$1 & " "; "")SI(C121!$C$5=E$2;C121!$B$1 & " "; "")SI(C122!$C$5=E$2;C122!$B$1 & " "; "")SI(C211!$C$5=E$2;C211!$B$1 & " "; "")SI(C212!$C$5=E$2;C212!$B$1 & " "; "")SI(C311!$C$5=E$2;C311!$B$1 & " "; "")SI(C312!$C$5=E$2;C312!$B$1 & " "; "")SI(C411!$C$5=E$2;C411!$B$1 & " "; "")SI(C412!$C$5=E$2;C412!$B$1 & " "; "")SI(D111!$C$5=E$2;D111!$B$1 & " "; "")SI(D211!$C$5=E$2;D211!$B$1 & " "; "")SI(D311!$C$5=E$2;D311!$B$1 & " "; "")SI(D411!$C$5=E$2;D411!$B$1 & " "; "")SI(M111!$C$5=E$2;M111!$B$1 & " "; "")SI(M211!$C$5=E$2;M211!$B$1 & " "; "")SI(M311!$C$5=E$2;M311!$B$1 & " "; "")SI(M411!$C$5=E$2;M411!$B$1 & " "; ""))); " "; ",") | F7: =SUSTITUIR(ESPACIOS(CONCATENAR(SI(C111!$C$5=F$2;C111!$B$1 & " "; "")SI(C121!$C$5=F$2;C121!$B$1 & " "; "")SI(C122!$C$5=F$2;C122!$B$1 & " "; "")SI(C211!$C$5=F$2;C211!$B$1 & " "; "")SI(C212!$C$5=F$2;C212!$B$1 & " "; "")SI(C311!$C$5=F$2;C311!$B$1 & " "; "")SI(C312!$C$5=F$2;C312!$B$1 & " "; "")SI(C411!$C$5=F$2;C411!$B$1 & " "; "")SI(C412!$C$5=F$2;C412!$B$1 & " "; "")SI(D111!$C$5=F$2;D111!$B$1 & " "; "")SI(D211!$C$5=F$2;D211!$B$1 & " "; "")SI(D311!$C$5=F$2;D311!$B$1 & " "; "")SI(D411!$C$5=F$2;D411!$B$1 & " "; "")SI(M111!$C$5=F$2;M111!$B$1 & " "; "")SI(M211!$C$5=F$2;M211!$B$1 & " "; "")SI(M311!$C$5=F$2;M311!$B$1 & " "; "")SI(M411!$C$5=F$2;M411!$B$1 & " "; ""))); " "; ",") | G7: =SUSTITUIR(ESPACIOS(CONCATENAR(SI(C111!$C$5=G$2;C111!$B$1 & " "; "")SI(C121!$C$5=G$2;C121!$B$1 & " "; "")SI(C122!$C$5=G$2;C122!$B$1 & " "; "")SI(C211!$C$5=G$2;C211!$B$1 & " "; "")SI(C212!$C$5=G$2;C212!$B$1 & " "; "")SI(C311!$C$5=G$2;C311!$B$1 & " "; "")SI(C312!$C$5=G$2;C312!$B$1 & " "; "")SI(C411!$C$5=G$2;C411!$B$1 & " "; "")SI(C412!$C$5=G$2;C412!$B$1 & " "; "")SI(D111!$C$5=G$2;D111!$B$1 & " "; "")SI(D211!$C$5=G$2;D211!$B$1 & " "; "")SI(D311!$C$5=G$2;D311!$B$1 & " "; "")SI(D411!$C$5=G$2;D411!$B$1 & " "; "")SI(M111!$C$5=G$2;M111!$B$1 & " "; "")SI(M211!$C$5=G$2;M211!$B$1 & " "; "")SI(M311!$C$5=G$2;M311!$B$1 & " "; "")SI(M411!$C$5=G$2;M411!$B$1 & " "; ""))); " "; ",") | H7: =SUSTITUIR(ESPACIOS(CONCATENAR(SI(C111!$C$5=H$2;C111!$B$1 & " "; "")SI(C121!$C$5=H$2;C121!$B$1 & " "; "")SI(C122!$C$5=H$2;C122!$B$1 & " "; "")SI(C211!$C$5=H$2;C211!$B$1 & " "; "")SI(C212!$C$5=H$2;C212!$B$1 & " "; "")SI(C311!$C$5=H$2;C311!$B$1 & " "; "")SI(C312!$C$5=H$2;C312!$B$1 & " "; "")SI(C411!$C$5=H$2;C411!$B$1 & " "; "")SI(C412!$C$5=H$2;C412!$B$1 & " "; "")SI(D111!$C$5=H$2;D111!$B$1 & " "; "")SI(D211!$C$5=H$2;D211!$B$1 & " "; "")SI(D311!$C$5=H$2;D311!$B$1 & " "; "")SI(D411!$C$5=H$2;D411!$B$1 & " "; "")SI(M111!$C$5=H$2;M111!$B$1 & " "; "")SI(M211!$C$5=H$2;M211!$B$1 & " "; "")SI(M311!$C$5=H$2;M311!$B$1 & " "; "")SI(M411!$C$5=H$2;M411!$B$1 & " "; ""))); " "; ",") | I7: =SUSTITUIR(ESPACIOS(CONCATENAR(SI(C111!$C$5=I$2;C111!$B$1 & " "; "")SI(C121!$C$5=I$2;C121!$B$1 & " "; "")SI(C122!$C$5=I$2;C122!$B$1 & " "; "")SI(C211!$C$5=I$2;C211!$B$1 & " "; "")SI(C212!$C$5=I$2;C212!$B$1 & " "; "")SI(C311!$C$5=I$2;C311!$B$1 & " "; "")SI(C312!$C$5=I$2;C312!$B$1 & " "; "")SI(C411!$C$5=I$2;C411!$B$1 & " "; "")SI(C412!$C$5=I$2;C412!$B$1 & " "; "")SI(D111!$C$5=I$2;D111!$B$1 & " "; "")SI(D211!$C$5=I$2;D211!$B$1 & " "; "")SI(D311!$C$5=I$2;D311!$B$1 & " "; "")SI(D411!$C$5=I$2;D411!$B$1 & " "; "")SI(M111!$C$5=I$2;M111!$B$1 & " "; "")SI(M211!$C$5=I$2;M211!$B$1 & " "; "")SI(M311!$C$5=I$2;M311!$B$1 & " "; "")SI(M411!$C$5=I$2;M411!$B$1 & " "; ""))); " "; ",") | J7: =SUSTITUIR(ESPACIOS(CONCATENAR(SI(C111!$C$5=J$2;C111!$B$1 & " "; "")SI(C121!$C$5=J$2;C121!$B$1 & " "; "")SI(C122!$C$5=J$2;C122!$B$1 & " "; "")SI(C211!$C$5=J$2;C211!$B$1 & " "; "")SI(C212!$C$5=J$2;C212!$B$1 & " "; "")SI(C311!$C$5=J$2;C311!$B$1 & " "; "")SI(C312!$C$5=J$2;C312!$B$1 & " "; "")SI(C411!$C$5=J$2;C411!$B$1 & " "; "")SI(C412!$C$5=J$2;C412!$B$1 & " "; "")SI(D111!$C$5=J$2;D111!$B$1 & " "; "")SI(D211!$C$5=J$2;D211!$B$1 & " "; "")SI(D311!$C$5=J$2;D311!$B$1 & " "; "")SI(D411!$C$5=J$2;D411!$B$1 & " "; "")SI(M111!$C$5=J$2;M111!$B$1 & " "; "")SI(M211!$C$5=J$2;M211!$B$1 & " "; "")SI(M311!$C$5=J$2;M311!$B$1 & " "; "")SI(M411!$C$5=J$2;M411!$B$1 & " "; ""))); " "; ",") | ... L7: =SUSTITUIR(ESPACIOS(CONCATENAR(SI(C111!$C$5=L$2;C111!$B$1 & " "; "")SI(C121!$C$5=L$2;C121!$B$1 & " "; "")SI(C122!$C$5=L$2;C122!$B$1 & " "; "")SI(C211!$C$5=L$2;C211!$B$1 & " "; "")SI(C212!$C$5=L$2;C212!$B$1 & " "; "")SI(C311!$C$5=L$2;C311!$B$1 & " "; "")SI(C312!$C$5=L$2;C312!$B$1 & " "; "")SI(C411!$C$5=L$2;C411!$B$1 & " "; "")SI(C412!$C$5=L$2;C412!$B$1 & " "; "")SI(D111!$C$5=L$2;D111!$B$1 & " "; "")SI(D211!$C$5=L$2;D211!$B$1 & " "; "")SI(D311!$C$5=L$2;D311!$B$1 & " "; "")SI(D411!$C$5=L$2;D411!$B$1 & " "; "")SI(M111!$C$5=L$2;M111!$B$1 & " "; "")SI(M211!$C$5=L$2;M211!$B$1 & " "; "")SI(M311!$C$5=L$2;M311!$B$1 & " "; "")SI(M411!$C$5=L$2;M411!$B$1 & " "; ""))); " "; ",")
A8: 6to | C8: =SUSTITUIR(ESPACIOS(CONCATENAR(SI(C111!$C$5=C$2;C111!$B$1 & " "; "")SI(C121!$C$5=C$2;C121!$B$1 & " "; "")SI(C122!$C$5=C$2;C122!$B$1 & " "; "")SI(C211!$C$5=C$2;C211!$B$1 & " "; "")SI(C212!$C$5=C$2;C212!$B$1 & " "; "")SI(C311!$C$5=C$2;C311!$B$1 & " "; "")SI(C312!$C$5=C$2;C312!$B$1 & " "; "")SI(C411!$C$5=C$2;C411!$B$1 & " "; "")SI(C412!$C$5=C$2;C412!$B$1 & " "; "")SI(D111!$C$5=C$2;D111!$B$1 & " "; "")SI(D211!$C$5=C$2;D211!$B$1 & " "; "")SI(D311!$C$5=C$2;D311!$B$1 & " "; "")SI(D411!$C$5=C$2;D411!$B$1 & " "; "")SI(M111!$C$5=C$2;M111!$B$1 & " "; "")SI(M211!$C$5=C$2;M211!$B$1 & " "; "")SI(M311!$C$5=C$2;M311!$B$1 & " "; "")SI(M411!$C$5=C$2;M411!$B$1 & " "; ""))); " "; ",") | D8: =SUSTITUIR(ESPACIOS(CONCATENAR(SI(C111!$C$5=D$2;C111!$B$1 & " "; "")SI(C121!$C$5=D$2;C121!$B$1 & " "; "")SI(C122!$C$5=D$2;C122!$B$1 & " "; "")SI(C211!$C$5=D$2;C211!$B$1 & " "; "")SI(C212!$C$5=D$2;C212!$B$1 & " "; "")SI(C311!$C$5=D$2;C311!$B$1 & " "; "")SI(C312!$C$5=D$2;C312!$B$1 & " "; "")SI(C411!$C$5=D$2;C411!$B$1 & " "; "")SI(C412!$C$5=D$2;C412!$B$1 & " "; "")SI(D111!$C$5=D$2;D111!$B$1 & " "; "")SI(D211!$C$5=D$2;D211!$B$1 & " "; "")SI(D311!$C$5=D$2;D311!$B$1 & " "; "")SI(D411!$C$5=D$2;D411!$B$1 & " "; "")SI(M111!$C$5=D$2;M111!$B$1 & " "; "")SI(M211!$C$5=D$2;M211!$B$1 & " "; "")SI(M311!$C$5=D$2;M311!$B$1 & " "; "")SI(M411!$C$5=D$2;M411!$B$1 & " "; ""))); " "; ",") | E8: =SUSTITUIR(ESPACIOS(CONCATENAR(SI(C111!$C$5=E$2;C111!$B$1 & " "; "")SI(C121!$C$5=E$2;C121!$B$1 & " "; "")SI(C122!$C$5=E$2;C122!$B$1 & " "; "")SI(C211!$C$5=E$2;C211!$B$1 & " "; "")SI(C212!$C$5=E$2;C212!$B$1 & " "; "")SI(C311!$C$5=E$2;C311!$B$1 & " "; "")SI(C312!$C$5=E$2;C312!$B$1 & " "; "")SI(C411!$C$5=E$2;C411!$B$1 & " "; "")SI(C412!$C$5=E$2;C412!$B$1 & " "; "")SI(D111!$C$5=E$2;D111!$B$1 & " "; "")SI(D211!$C$5=E$2;D211!$B$1 & " "; "")SI(D311!$C$5=E$2;D311!$B$1 & " "; "")SI(D411!$C$5=E$2;D411!$B$1 & " "; "")SI(M111!$C$5=E$2;M111!$B$1 & " "; "")SI(M211!$C$5=E$2;M211!$B$1 & " "; "")SI(M311!$C$5=E$2;M311!$B$1 & " "; "")SI(M411!$C$5=E$2;M411!$B$1 & " "; ""))); " "; ",") | F8: =SUSTITUIR(ESPACIOS(CONCATENAR(SI(C111!$C$5=F$2;C111!$B$1 & " "; "")SI(C121!$C$5=F$2;C121!$B$1 & " "; "")SI(C122!$C$5=F$2;C122!$B$1 & " "; "")SI(C211!$C$5=F$2;C211!$B$1 & " "; "")SI(C212!$C$5=F$2;C212!$B$1 & " "; "")SI(C311!$C$5=F$2;C311!$B$1 & " "; "")SI(C312!$C$5=F$2;C312!$B$1 & " "; "")SI(C411!$C$5=F$2;C411!$B$1 & " "; "")SI(C412!$C$5=F$2;C412!$B$1 & " "; "")SI(D111!$C$5=F$2;D111!$B$1 & " "; "")SI(D211!$C$5=F$2;D211!$B$1 & " "; "")SI(D311!$C$5=F$2;D311!$B$1 & " "; "")SI(D411!$C$5=F$2;D411!$B$1 & " "; "")SI(M111!$C$5=F$2;M111!$B$1 & " "; "")SI(M211!$C$5=F$2;M211!$B$1 & " "; "")SI(M311!$C$5=F$2;M311!$B$1 & " "; "")SI(M411!$C$5=F$2;M411!$B$1 & " "; ""))); " "; ",") | G8: =SUSTITUIR(ESPACIOS(CONCATENAR(SI(C111!$C$5=G$2;C111!$B$1 & " "; "")SI(C121!$C$5=G$2;C121!$B$1 & " "; "")SI(C122!$C$5=G$2;C122!$B$1 & " "; "")SI(C211!$C$5=G$2;C211!$B$1 & " "; "")SI(C212!$C$5=G$2;C212!$B$1 & " "; "")SI(C311!$C$5=G$2;C311!$B$1 & " "; "")SI(C312!$C$5=G$2;C312!$B$1 & " "; "")SI(C411!$C$5=G$2;C411!$B$1 & " "; "")SI(C412!$C$5=G$2;C412!$B$1 & " "; "")SI(D111!$C$5=G$2;D111!$B$1 & " "; "")SI(D211!$C$5=G$2;D211!$B$1 & " "; "")SI(D311!$C$5=G$2;D311!$B$1 & " "; "")SI(D411!$C$5=G$2;D411!$B$1 & " "; "")SI(M111!$C$5=G$2;M111!$B$1 & " "; "")SI(M211!$C$5=G$2;M211!$B$1 & " "; "")SI(M311!$C$5=G$2;M311!$B$1 & " "; "")SI(M411!$C$5=G$2;M411!$B$1 & " "; ""))); " "; ",") | H8: =SUSTITUIR(ESPACIOS(CONCATENAR(SI(C111!$C$5=H$2;C111!$B$1 & " "; "")SI(C121!$C$5=H$2;C121!$B$1 & " "; "")SI(C122!$C$5=H$2;C122!$B$1 & " "; "")SI(C211!$C$5=H$2;C211!$B$1 & " "; "")SI(C212!$C$5=H$2;C212!$B$1 & " "; "")SI(C311!$C$5=H$2;C311!$B$1 & " "; "")SI(C312!$C$5=H$2;C312!$B$1 & " "; "")SI(C411!$C$5=H$2;C411!$B$1 & " "; "")SI(C412!$C$5=H$2;C412!$B$1 & " "; "")SI(D111!$C$5=H$2;D111!$B$1 & " "; "")SI(D211!$C$5=H$2;D211!$B$1 & " "; "")SI(D311!$C$5=H$2;D311!$B$1 & " "; "")SI(D411!$C$5=H$2;D411!$B$1 & " "; "")SI(M111!$C$5=H$2;M111!$B$1 & " "; "")SI(M211!$C$5=H$2;M211!$B$1 & " "; "")SI(M311!$C$5=H$2;M311!$B$1 & " "; "")SI(M411!$C$5=H$2;M411!$B$1 & " "; ""))); " "; ",") | I8: =SUSTITUIR(ESPACIOS(CONCATENAR(SI(C111!$C$5=I$2;C111!$B$1 & " "; "")SI(C121!$C$5=I$2;C121!$B$1 & " "; "")SI(C122!$C$5=I$2;C122!$B$1 & " "; "")SI(C211!$C$5=I$2;C211!$B$1 & " "; "")SI(C212!$C$5=I$2;C212!$B$1 & " "; "")SI(C311!$C$5=I$2;C311!$B$1 & " "; "")SI(C312!$C$5=I$2;C312!$B$1 & " "; "")SI(C411!$C$5=I$2;C411!$B$1 & " "; "")SI(C412!$C$5=I$2;C412!$B$1 & " "; "")SI(D111!$C$5=I$2;D111!$B$1 & " "; "")SI(D211!$C$5=I$2;D211!$B$1 & " "; "")SI(D311!$C$5=I$2;D311!$B$1 & " "; "")SI(D411!$C$5=I$2;D411!$B$1 & " "; "")SI(M111!$C$5=I$2;M111!$B$1 & " "; "")SI(M211!$C$5=I$2;M211!$B$1 & " "; "")SI(M311!$C$5=I$2;M311!$B$1 & " "; "")SI(M411!$C$5=I$2;M411!$B$1 & " "; ""))); " "; ",") | J8: =SUSTITUIR(ESPACIOS(CONCATENAR(SI(C111!$C$5=J$2;C111!$B$1 & " "; "")SI(C121!$C$5=J$2;C121!$B$1 & " "; "")SI(C122!$C$5=J$2;C122!$B$1 & " "; "")SI(C211!$C$5=J$2;C211!$B$1 & " "; "")SI(C212!$C$5=J$2;C212!$B$1 & " "; "")SI(C311!$C$5=J$2;C311!$B$1 & " "; "")SI(C312!$C$5=J$2;C312!$B$1 & " "; "")SI(C411!$C$5=J$2;C411!$B$1 & " "; "")SI(C412!$C$5=J$2;C412!$B$1 & " "; "")SI(D111!$C$5=J$2;D111!$B$1 & " "; "")SI(D211!$C$5=J$2;D211!$B$1 & " "; "")SI(D311!$C$5=J$2;D311!$B$1 & " "; "")SI(D411!$C$5=J$2;D411!$B$1 & " "; "")SI(M111!$C$5=J$2;M111!$B$1 & " "; "")SI(M211!$C$5=J$2;M211!$B$1 & " "; "")SI(M311!$C$5=J$2;M311!$B$1 & " "; "")SI(M411!$C$5=J$2;M411!$B$1 & " "; ""))); " "; ",") | ... L8: =SUSTITUIR(ESPACIOS(CONCATENAR(SI(C111!$C$5=L$2;C111!$B$1 & " "; "")SI(C121!$C$5=L$2;C121!$B$1 & " "; "")SI(C122!$C$5=L$2;C122!$B$1 & " "; "")SI(C211!$C$5=L$2;C211!$B$1 & " "; "")SI(C212!$C$5=L$2;C212!$B$1 & " "; "")SI(C311!$C$5=L$2;C311!$B$1 & " "; "")SI(C312!$C$5=L$2;C312!$B$1 & " "; "")SI(C411!$C$5=L$2;C411!$B$1 & " "; "")SI(C412!$C$5=L$2;C412!$B$1 & " "; "")SI(D111!$C$5=L$2;D111!$B$1 & " "; "")SI(D211!$C$5=L$2;D211!$B$1 & " "; "")SI(D311!$C$5=L$2;D311!$B$1 & " "; "")SI(D411!$C$5=L$2;D411!$B$1 & " "; "")SI(M111!$C$5=L$2;M111!$B$1 & " "; "")SI(M211!$C$5=L$2;M211!$B$1 & " "; "")SI(M311!$C$5=L$2;M311!$B$1 & " "; "")SI(M411!$C$5=L$2;M411!$B$1 & " "; ""))); " "; ",")
A9: Martes | C9: =SUSTITUIR(ESPACIOS(CONCATENAR(SI(C111!$C$5=C$2;C111!$B$1 & " "; "")SI(C121!$C$5=C$2;C121!$B$1 & " "; "")SI(C122!$C$5=C$2;C122!$B$1 & " "; "")SI(C211!$C$5=C$2;C211!$B$1 & " "; "")SI(C212!$C$5=C$2;C212!$B$1 & " "; "")SI(C311!$C$5=C$2;C311!$B$1 & " "; "")SI(C312!$C$5=C$2;C312!$B$1 & " "; "")SI(C411!$C$5=C$2;C411!$B$1 & " "; "")SI(C412!$C$5=C$2;C412!$B$1 & " "; "")SI(D111!$C$5=C$2;D111!$B$1 & " "; "")SI(D211!$C$5=C$2;D211!$B$1 & " "; "")SI(D311!$C$5=C$2;D311!$B$1 & " "; "")SI(D411!$C$5=C$2;D411!$B$1 & " "; "")SI(M111!$C$5=C$2;M111!$B$1 & " "; "")SI(M211!$C$5=C$2;M211!$B$1 & " "; "")SI(M311!$C$5=C$2;M311!$B$1 & " "; "")SI(M411!$C$5=C$2;M411!$B$1 & " "; ""))); " "; ",") | D9: =SUSTITUIR(ESPACIOS(CONCATENAR(SI(C111!$C$5=D$2;C111!$B$1 & " "; "")SI(C121!$C$5=D$2;C121!$B$1 & " "; "")SI(C122!$C$5=D$2;C122!$B$1 & " "; "")SI(C211!$C$5=D$2;C211!$B$1 & " "; "")SI(C212!$C$5=D$2;C212!$B$1 & " "; "")SI(C311!$C$5=D$2;C311!$B$1 & " "; "")SI(C312!$C$5=D$2;C312!$B$1 & " "; "")SI(C411!$C$5=D$2;C411!$B$1 & " "; "")SI(C412!$C$5=D$2;C412!$B$1 & " "; "")SI(D111!$C$5=D$2;D111!$B$1 & " "; "")SI(D211!$C$5=D$2;D211!$B$1 & " "; "")SI(D311!$C$5=D$2;D311!$B$1 & " "; "")SI(D411!$C$5=D$2;D411!$B$1 & " "; "")SI(M111!$C$5=D$2;M111!$B$1 & " "; "")SI(M211!$C$5=D$2;M211!$B$1 & " "; "")SI(M311!$C$5=D$2;M311!$B$1 & " "; "")SI(M411!$C$5=D$2;M411!$B$1 & " "; ""))); " "; ",") | E9: =SUSTITUIR(ESPACIOS(CONCATENAR(SI(C111!$C$5=E$2;C111!$B$1 & " "; "")SI(C121!$C$5=E$2;C121!$B$1 & " "; "")SI(C122!$C$5=E$2;C122!$B$1 & " "; "")SI(C211!$C$5=E$2;C211!$B$1 & " "; "")SI(C212!$C$5=E$2;C212!$B$1 & " "; "")SI(C311!$C$5=E$2;C311!$B$1 & " "; "")SI(C312!$C$5=E$2;C312!$B$1 & " "; "")SI(C411!$C$5=E$2;C411!$B$1 & " "; "")SI(C412!$C$5=E$2;C412!$B$1 & " "; "")SI(D111!$C$5=E$2;D111!$B$1 & " "; "")SI(D211!$C$5=E$2;D211!$B$1 & " "; "")SI(D311!$C$5=E$2;D311!$B$1 & " "; "")SI(D411!$C$5=E$2;D411!$B$1 & " "; "")SI(M111!$C$5=E$2;M111!$B$1 & " "; "")SI(M211!$C$5=E$2;M211!$B$1 & " "; "")SI(M311!$C$5=E$2;M311!$B$1 & " "; "")SI(M411!$C$5=E$2;M411!$B$1 & " "; ""))); " "; ",") | F9: =SUSTITUIR(ESPACIOS(CONCATENAR(SI(C111!$C$5=F$2;C111!$B$1 & " "; "")SI(C121!$C$5=F$2;C121!$B$1 & " "; "")SI(C122!$C$5=F$2;C122!$B$1 & " "; "")SI(C211!$C$5=F$2;C211!$B$1 & " "; "")SI(C212!$C$5=F$2;C212!$B$1 & " "; "")SI(C311!$C$5=F$2;C311!$B$1 & " "; "")SI(C312!$C$5=F$2;C312!$B$1 & " "; "")SI(C411!$C$5=F$2;C411!$B$1 & " "; "")SI(C412!$C$5=F$2;C412!$B$1 & " "; "")SI(D111!$C$5=F$2;D111!$B$1 & " "; "")SI(D211!$C$5=F$2;D211!$B$1 & " "; "")SI(D311!$C$5=F$2;D311!$B$1 & " "; "")SI(D411!$C$5=F$2;D411!$B$1 & " "; "")SI(M111!$C$5=F$2;M111!$B$1 & " "; "")SI(M211!$C$5=F$2;M211!$B$1 & " "; "")SI(M311!$C$5=F$2;M311!$B$1 & " "; "")SI(M411!$C$5=F$2;M411!$B$1 & " "; ""))); " "; ",") | G9: =SUSTITUIR(ESPACIOS(CONCATENAR(SI(C111!$C$5=G$2;C111!$B$1 & " "; "")SI(C121!$C$5=G$2;C121!$B$1 & " "; "")SI(C122!$C$5=G$2;C122!$B$1 & " "; "")SI(C211!$C$5=G$2;C211!$B$1 & " "; "")SI(C212!$C$5=G$2;C212!$B$1 & " "; "")SI(C311!$C$5=G$2;C311!$B$1 & " "; "")SI(C312!$C$5=G$2;C312!$B$1 & " "; "")SI(C411!$C$5=G$2;C411!$B$1 & " "; "")SI(C412!$C$5=G$2;C412!$B$1 & " "; "")SI(D111!$C$5=G$2;D111!$B$1 & " "; "")SI(D211!$C$5=G$2;D211!$B$1 & " "; "")SI(D311!$C$5=G$2;D311!$B$1 & " "; "")SI(D411!$C$5=G$2;D411!$B$1 & " "; "")SI(M111!$C$5=G$2;M111!$B$1 & " "; "")SI(M211!$C$5=G$2;M211!$B$1 & " "; "")SI(M311!$C$5=G$2;M311!$B$1 & " "; "")SI(M411!$C$5=G$2;M411!$B$1 & " "; ""))); " "; ",") | H9: =SUSTITUIR(ESPACIOS(CONCATENAR(SI(C111!$C$5=H$2;C111!$B$1 & " "; "")SI(C121!$C$5=H$2;C121!$B$1 & " "; "")SI(C122!$C$5=H$2;C122!$B$1 & " "; "")SI(C211!$C$5=H$2;C211!$B$1 & " "; "")SI(C212!$C$5=H$2;C212!$B$1 & " "; "")SI(C311!$C$5=H$2;C311!$B$1 & " "; "")SI(C312!$C$5=H$2;C312!$B$1 & " "; "")SI(C411!$C$5=H$2;C411!$B$1 & " "; "")SI(C412!$C$5=H$2;C412!$B$1 & " "; "")SI(D111!$C$5=H$2;D111!$B$1 & " "; "")SI(D211!$C$5=H$2;D211!$B$1 & " "; "")SI(D311!$C$5=H$2;D311!$B$1 & " "; "")SI(D411!$C$5=H$2;D411!$B$1 & " "; "")SI(M111!$C$5=H$2;M111!$B$1 & " "; "")SI(M211!$C$5=H$2;M211!$B$1 & " "; "")SI(M311!$C$5=H$2;M311!$B$1 & " "; "")SI(M411!$C$5=H$2;M411!$B$1 & " "; ""))); " "; ",") | I9: =SUSTITUIR(ESPACIOS(CONCATENAR(SI(C111!$C$5=I$2;C111!$B$1 & " "; "")SI(C121!$C$5=I$2;C121!$B$1 & " "; "")SI(C122!$C$5=I$2;C122!$B$1 & " "; "")SI(C211!$C$5=I$2;C211!$B$1 & " "; "")SI(C212!$C$5=I$2;C212!$B$1 & " "; "")SI(C311!$C$5=I$2;C311!$B$1 & " "; "")SI(C312!$C$5=I$2;C312!$B$1 & " "; "")SI(C411!$C$5=I$2;C411!$B$1 & " "; "")SI(C412!$C$5=I$2;C412!$B$1 & " "; "")SI(D111!$C$5=I$2;D111!$B$1 & " "; "")SI(D211!$C$5=I$2;D211!$B$1 & " "; "")SI(D311!$C$5=I$2;D311!$B$1 & " "; "")SI(D411!$C$5=I$2;D411!$B$1 & " "; "")SI(M111!$C$5=I$2;M111!$B$1 & " "; "")SI(M211!$C$5=I$2;M211!$B$1 & " "; "")SI(M311!$C$5=I$2;M311!$B$1 & " "; "")SI(M411!$C$5=I$2;M411!$B$1 & " "; ""))); " "; ",") | J9: =SUSTITUIR(ESPACIOS(CONCATENAR(SI(C111!$C$5=J$2;C111!$B$1 & " "; "")SI(C121!$C$5=J$2;C121!$B$1 & " "; "")SI(C122!$C$5=J$2;C122!$B$1 & " "; "")SI(C211!$C$5=J$2;C211!$B$1 & " "; "")SI(C212!$C$5=J$2;C212!$B$1 & " "; "")SI(C311!$C$5=J$2;C311!$B$1 & " "; "")SI(C312!$C$5=J$2;C312!$B$1 & " "; "")SI(C411!$C$5=J$2;C411!$B$1 & " "; "")SI(C412!$C$5=J$2;C412!$B$1 & " "; "")SI(D111!$C$5=J$2;D111!$B$1 & " "; "")SI(D211!$C$5=J$2;D211!$B$1 & " "; "")SI(D311!$C$5=J$2;D311!$B$1 & " "; "")SI(D411!$C$5=J$2;D411!$B$1 & " "; "")SI(M111!$C$5=J$2;M111!$B$1 & " "; "")SI(M211!$C$5=J$2;M211!$B$1 & " "; "")SI(M311!$C$5=J$2;M311!$B$1 & " "; "")SI(M411!$C$5=J$2;M411!$B$1 & " "; ""))); " "; ",") | ... L9: =SUSTITUIR(ESPACIOS(CONCATENAR(SI(C111!$C$5=L$2;C111!$B$1 & " "; "")SI(C121!$C$5=L$2;C121!$B$1 & " "; "")SI(C122!$C$5=L$2;C122!$B$1 & " "; "")SI(C211!$C$5=L$2;C211!$B$1 & " "; "")SI(C212!$C$5=L$2;C212!$B$1 & " "; "")SI(C311!$C$5=L$2;C311!$B$1 & " "; "")SI(C312!$C$5=L$2;C312!$B$1 & " "; "")SI(C411!$C$5=L$2;C411!$B$1 & " "; "")SI(C412!$C$5=L$2;C412!$B$1 & " "; "")SI(D111!$C$5=L$2;D111!$B$1 & " "; "")SI(D211!$C$5=L$2;D211!$B$1 & " "; "")SI(D311!$C$5=L$2;D311!$B$1 & " "; "")SI(D411!$C$5=L$2;D411!$B$1 & " "; "")SI(M111!$C$5=L$2;M111!$B$1 & " "; "")SI(M211!$C$5=L$2;M211!$B$1 & " "; "")SI(M311!$C$5=L$2;M311!$B$1 & " "; "")SI(M411!$C$5=L$2;M411!$B$1 & " "; ""))); " "; ",")
A10: 1ro | C10: =SUSTITUIR(ESPACIOS(CONCATENAR(SI(C111!$C$5=C$2;C111!$B$1 & " "; "")SI(C121!$C$5=C$2;C121!$B$1 & " "; "")SI(C122!$C$5=C$2;C122!$B$1 & " "; "")SI(C211!$C$5=C$2;C211!$B$1 & " "; "")SI(C212!$C$5=C$2;C212!$B$1 & " "; "")SI(C311!$C$5=C$2;C311!$B$1 & " "; "")SI(C312!$C$5=C$2;C312!$B$1 & " "; "")SI(C411!$C$5=C$2;C411!$B$1 & " "; "")SI(C412!$C$5=C$2;C412!$B$1 & " "; "")SI(D111!$C$5=C$2;D111!$B$1 & " "; "")SI(D211!$C$5=C$2;D211!$B$1 & " "; "")SI(D311!$C$5=C$2;D311!$B$1 & " "; "")SI(D411!$C$5=C$2;D411!$B$1 & " "; "")SI(M111!$C$5=C$2;M111!$B$1 & " "; "")SI(M211!$C$5=C$2;M211!$B$1 & " "; "")SI(M311!$C$5=C$2;M311!$B$1 & " "; "")SI(M411!$C$5=C$2;M411!$B$1 & " "; ""))); " "; ",") | D10: =SUSTITUIR(ESPACIOS(CONCATENAR(SI(C111!$C$5=D$2;C111!$B$1 & " "; "")SI(C121!$C$5=D$2;C121!$B$1 & " "; "")SI(C122!$C$5=D$2;C122!$B$1 & " "; "")SI(C211!$C$5=D$2;C211!$B$1 & " "; "")SI(C212!$C$5=D$2;C212!$B$1 & " "; "")SI(C311!$C$5=D$2;C311!$B$1 & " "; "")SI(C312!$C$5=D$2;C312!$B$1 & " "; "")SI(C411!$C$5=D$2;C411!$B$1 & " "; "")SI(C412!$C$5=D$2;C412!$B$1 & " "; "")SI(D111!$C$5=D$2;D111!$B$1 & " "; "")SI(D211!$C$5=D$2;D211!$B$1 & " "; "")SI(D311!$C$5=D$2;D311!$B$1 & " "; "")SI(D411!$C$5=D$2;D411!$B$1 & " "; "")SI(M111!$C$5=D$2;M111!$B$1 & " "; "")SI(M211!$C$5=D$2;M211!$B$1 & " "; "")SI(M311!$C$5=D$2;M311!$B$1 & " "; "")SI(M411!$C$5=D$2;M411!$B$1 & " "; ""))); " "; ",") | E10: =SUSTITUIR(ESPACIOS(CONCATENAR(SI(C111!$C$5=E$2;C111!$B$1 & " "; "")SI(C121!$C$5=E$2;C121!$B$1 & " "; "")SI(C122!$C$5=E$2;C122!$B$1 & " "; "")SI(C211!$C$5=E$2;C211!$B$1 & " "; "")SI(C212!$C$5=E$2;C212!$B$1 & " "; "")SI(C311!$C$5=E$2;C311!$B$1 & " "; "")SI(C312!$C$5=E$2;C312!$B$1 & " "; "")SI(C411!$C$5=E$2;C411!$B$1 & " "; "")SI(C412!$C$5=E$2;C412!$B$1 & " "; "")SI(D111!$C$5=E$2;D111!$B$1 & " "; "")SI(D211!$C$5=E$2;D211!$B$1 & " "; "")SI(D311!$C$5=E$2;D311!$B$1 & " "; "")SI(D411!$C$5=E$2;D411!$B$1 & " "; "")SI(M111!$C$5=E$2;M111!$B$1 & " "; "")SI(M211!$C$5=E$2;M211!$B$1 & " "; "")SI(M311!$C$5=E$2;M311!$B$1 & " "; "")SI(M411!$C$5=E$2;M411!$B$1 & " "; ""))); " "; ",") | F10: =SUSTITUIR(ESPACIOS(CONCATENAR(SI(C111!$C$5=F$2;C111!$B$1 & " "; "")SI(C121!$C$5=F$2;C121!$B$1 & " "; "")SI(C122!$C$5=F$2;C122!$B$1 & " "; "")SI(C211!$C$5=F$2;C211!$B$1 & " "; "")SI(C212!$C$5=F$2;C212!$B$1 & " "; "")SI(C311!$C$5=F$2;C311!$B$1 & " "; "")SI(C312!$C$5=F$2;C312!$B$1 & " "; "")SI(C411!$C$5=F$2;C411!$B$1 & " "; "")SI(C412!$C$5=F$2;C412!$B$1 & " "; "")SI(D111!$C$5=F$2;D111!$B$1 & " "; "")SI(D211!$C$5=F$2;D211!$B$1 & " "; "")SI(D311!$C$5=F$2;D311!$B$1 & " "; "")SI(D411!$C$5=F$2;D411!$B$1 & " "; "")SI(M111!$C$5=F$2;M111!$B$1 & " "; "")SI(M211!$C$5=F$2;M211!$B$1 & " "; "")SI(M311!$C$5=F$2;M311!$B$1 & " "; "")SI(M411!$C$5=F$2;M411!$B$1 & " "; ""))); " "; ",") | G10: =SUSTITUIR(ESPACIOS(CONCATENAR(SI(C111!$C$5=G$2;C111!$B$1 & " "; "")SI(C121!$C$5=G$2;C121!$B$1 & " "; "")SI(C122!$C$5=G$2;C122!$B$1 & " "; "")SI(C211!$C$5=G$2;C211!$B$1 & " "; "")SI(C212!$C$5=G$2;C212!$B$1 & " "; "")SI(C311!$C$5=G$2;C311!$B$1 & " "; "")SI(C312!$C$5=G$2;C312!$B$1 & " "; "")SI(C411!$C$5=G$2;C411!$B$1 & " "; "")SI(C412!$C$5=G$2;C412!$B$1 & " "; "")SI(D111!$C$5=G$2;D111!$B$1 & " "; "")SI(D211!$C$5=G$2;D211!$B$1 & " "; "")SI(D311!$C$5=G$2;D311!$B$1 & " "; "")SI(D411!$C$5=G$2;D411!$B$1 & " "; "")SI(M111!$C$5=G$2;M111!$B$1 & " "; "")SI(M211!$C$5=G$2;M211!$B$1 & " "; "")SI(M311!$C$5=G$2;M311!$B$1 & " "; "")SI(M411!$C$5=G$2;M411!$B$1 & " "; ""))); " "; ",") | H10: =SUSTITUIR(ESPACIOS(CONCATENAR(SI(C111!$C$5=H$2;C111!$B$1 & " "; "")SI(C121!$C$5=H$2;C121!$B$1 & " "; "")SI(C122!$C$5=H$2;C122!$B$1 & " "; "")SI(C211!$C$5=H$2;C211!$B$1 & " "; "")SI(C212!$C$5=H$2;C212!$B$1 & " "; "")SI(C311!$C$5=H$2;C311!$B$1 & " "; "")SI(C312!$C$5=H$2;C312!$B$1 & " "; "")SI(C411!$C$5=H$2;C411!$B$1 & " "; "")SI(C412!$C$5=H$2;C412!$B$1 & " "; "")SI(D111!$C$5=H$2;D111!$B$1 & " "; "")SI(D211!$C$5=H$2;D211!$B$1 & " "; "")SI(D311!$C$5=H$2;D311!$B$1 & " "; "")SI(D411!$C$5=H$2;D411!$B$1 & " "; "")SI(M111!$C$5=H$2;M111!$B$1 & " "; "")SI(M211!$C$5=H$2;M211!$B$1 & " "; "")SI(M311!$C$5=H$2;M311!$B$1 & " "; "")SI(M411!$C$5=H$2;M411!$B$1 & " "; ""))); " "; ",") | I10: =SUSTITUIR(ESPACIOS(CONCATENAR(SI(C111!$C$5=I$2;C111!$B$1 & " "; "")SI(C121!$C$5=I$2;C121!$B$1 & " "; "")SI(C122!$C$5=I$2;C122!$B$1 & " "; "")SI(C211!$C$5=I$2;C211!$B$1 & " "; "")SI(C212!$C$5=I$2;C212!$B$1 & " "; "")SI(C311!$C$5=I$2;C311!$B$1 & " "; "")SI(C312!$C$5=I$2;C312!$B$1 & " "; "")SI(C411!$C$5=I$2;C411!$B$1 & " "; "")SI(C412!$C$5=I$2;C412!$B$1 & " "; "")SI(D111!$C$5=I$2;D111!$B$1 & " "; "")SI(D211!$C$5=I$2;D211!$B$1 & " "; "")SI(D311!$C$5=I$2;D311!$B$1 & " "; "")SI(D411!$C$5=I$2;D411!$B$1 & " "; "")SI(M111!$C$5=I$2;M111!$B$1 & " "; "")SI(M211!$C$5=I$2;M211!$B$1 & " "; "")SI(M311!$C$5=I$2;M311!$B$1 & " "; "")SI(M411!$C$5=I$2;M411!$B$1 & " "; ""))); " "; ",") | J10: =SUSTITUIR(ESPACIOS(CONCATENAR(SI(C111!$C$5=J$2;C111!$B$1 & " "; "")SI(C121!$C$5=J$2;C121!$B$1 & " "; "")SI(C122!$C$5=J$2;C122!$B$1 & " "; "")SI(C211!$C$5=J$2;C211!$B$1 & " "; "")SI(C212!$C$5=J$2;C212!$B$1 & " "; "")SI(C311!$C$5=J$2;C311!$B$1 & " "; "")SI(C312!$C$5=J$2;C312!$B$1 & " "; "")SI(C411!$C$5=J$2;C411!$B$1 & " "; "")SI(C412!$C$5=J$2;C412!$B$1 & " "; "")SI(D111!$C$5=J$2;D111!$B$1 & " "; "")SI(D211!$C$5=J$2;D211!$B$1 & " "; "")SI(D311!$C$5=J$2;D311!$B$1 & " "; "")SI(D411!$C$5=J$2;D411!$B$1 & " "; "")SI(M111!$C$5=J$2;M111!$B$1 & " "; "")SI(M211!$C$5=J$2;M211!$B$1 & " "; "")SI(M311!$C$5=J$2;M311!$B$1 & " "; "")SI(M411!$C$5=J$2;M411!$B$1 & " "; ""))); " "; ",") | ... L10: =SUSTITUIR(ESPACIOS(CONCATENAR(SI(C111!$C$5=L$2;C111!$B$1 & " "; "")SI(C121!$C$5=L$2;C121!$B$1 & " "; "")SI(C122!$C$5=L$2;C122!$B$1 & " "; "")SI(C211!$C$5=L$2;C211!$B$1 & " "; "")SI(C212!$C$5=L$2;C212!$B$1 & " "; "")SI(C311!$C$5=L$2;C311!$B$1 & " "; "")SI(C312!$C$5=L$2;C312!$B$1 & " "; "")SI(C411!$C$5=L$2;C411!$B$1 & " "; "")SI(C412!$C$5=L$2;C412!$B$1 & " "; "")SI(D111!$C$5=L$2;D111!$B$1 & " "; "")SI(D211!$C$5=L$2;D211!$B$1 & " "; "")SI(D311!$C$5=L$2;D311!$B$1 & " "; "")SI(D411!$C$5=L$2;D411!$B$1 & " "; "")SI(M111!$C$5=L$2;M111!$B$1 & " "; "")SI(M211!$C$5=L$2;M211!$B$1 & " "; "")SI(M311!$C$5=L$2;M311!$B$1 & " "; "")SI(M411!$C$5=L$2;M411!$B$1 & " "; ""))); " "; ",")
A11: 2do | C11: =SUSTITUIR(ESPACIOS(CONCATENAR(SI(C111!$C$5=C$2;C111!$B$1 & " "; "")SI(C121!$C$5=C$2;C121!$B$1 & " "; "")SI(C122!$C$5=C$2;C122!$B$1 & " "; "")SI(C211!$C$5=C$2;C211!$B$1 & " "; "")SI(C212!$C$5=C$2;C212!$B$1 & " "; "")SI(C311!$C$5=C$2;C311!$B$1 & " "; "")SI(C312!$C$5=C$2;C312!$B$1 & " "; "")SI(C411!$C$5=C$2;C411!$B$1 & " "; "")SI(C412!$C$5=C$2;C412!$B$1 & " "; "")SI(D111!$C$5=C$2;D111!$B$1 & " "; "")SI(D211!$C$5=C$2;D211!$B$1 & " "; "")SI(D311!$C$5=C$2;D311!$B$1 & " "; "")SI(D411!$C$5=C$2;D411!$B$1 & " "; "")SI(M111!$C$5=C$2;M111!$B$1 & " "; "")SI(M211!$C$5=C$2;M211!$B$1 & " "; "")SI(M311!$C$5=C$2;M311!$B$1 & " "; "")SI(M411!$C$5=C$2;M411!$B$1 & " "; ""))); " "; ",") | D11: =SUSTITUIR(ESPACIOS(CONCATENAR(SI(C111!$C$5=D$2;C111!$B$1 & " "; "")SI(C121!$C$5=D$2;C121!$B$1 & " "; "")SI(C122!$C$5=D$2;C122!$B$1 & " "; "")SI(C211!$C$5=D$2;C211!$B$1 & " "; "")SI(C212!$C$5=D$2;C212!$B$1 & " "; "")SI(C311!$C$5=D$2;C311!$B$1 & " "; "")SI(C312!$C$5=D$2;C312!$B$1 & " "; "")SI(C411!$C$5=D$2;C411!$B$1 & " "; "")SI(C412!$C$5=D$2;C412!$B$1 & " "; "")SI(D111!$C$5=D$2;D111!$B$1 & " "; "")SI(D211!$C$5=D$2;D211!$B$1 & " "; "")SI(D311!$C$5=D$2;D311!$B$1 & " "; "")SI(D411!$C$5=D$2;D411!$B$1 & " "; "")SI(M111!$C$5=D$2;M111!$B$1 & " "; "")SI(M211!$C$5=D$2;M211!$B$1 & " "; "")SI(M311!$C$5=D$2;M311!$B$1 & " "; "")SI(M411!$C$5=D$2;M411!$B$1 & " "; ""))); " "; ",") | E11: =SUSTITUIR(ESPACIOS(CONCATENAR(SI(C111!$C$5=E$2;C111!$B$1 & " "; "")SI(C121!$C$5=E$2;C121!$B$1 & " "; "")SI(C122!$C$5=E$2;C122!$B$1 & " "; "")SI(C211!$C$5=E$2;C211!$B$1 & " "; "")SI(C212!$C$5=E$2;C212!$B$1 & " "; "")SI(C311!$C$5=E$2;C311!$B$1 & " "; "")SI(C312!$C$5=E$2;C312!$B$1 & " "; "")SI(C411!$C$5=E$2;C411!$B$1 & " "; "")SI(C412!$C$5=E$2;C412!$B$1 & " "; "")SI(D111!$C$5=E$2;D111!$B$1 & " "; "")SI(D211!$C$5=E$2;D211!$B$1 & " "; "")SI(D311!$C$5=E$2;D311!$B$1 & " "; "")SI(D411!$C$5=E$2;D411!$B$1 & " "; "")SI(M111!$C$5=E$2;M111!$B$1 & " "; "")SI(M211!$C$5=E$2;M211!$B$1 & " "; "")SI(M311!$C$5=E$2;M311!$B$1 & " "; "")SI(M411!$C$5=E$2;M411!$B$1 & " "; ""))); " "; ",") | F11: =SUSTITUIR(ESPACIOS(CONCATENAR(SI(C111!$C$5=F$2;C111!$B$1 & " "; "")SI(C121!$C$5=F$2;C121!$B$1 & " "; "")SI(C122!$C$5=F$2;C122!$B$1 & " "; "")SI(C211!$C$5=F$2;C211!$B$1 & " "; "")SI(C212!$C$5=F$2;C212!$B$1 & " "; "")SI(C311!$C$5=F$2;C311!$B$1 & " "; "")SI(C312!$C$5=F$2;C312!$B$1 & " "; "")SI(C411!$C$5=F$2;C411!$B$1 & " "; "")SI(C412!$C$5=F$2;C412!$B$1 & " "; "")SI(D111!$C$5=F$2;D111!$B$1 & " "; "")SI(D211!$C$5=F$2;D211!$B$1 & " "; "")SI(D311!$C$5=F$2;D311!$B$1 & " "; "")SI(D411!$C$5=F$2;D411!$B$1 & " "; "")SI(M111!$C$5=F$2;M111!$B$1 & " "; "")SI(M211!$C$5=F$2;M211!$B$1 & " "; "")SI(M311!$C$5=F$2;M311!$B$1 & " "; "")SI(M411!$C$5=F$2;M411!$B$1 & " "; ""))); " "; ",") | G11: =SUSTITUIR(ESPACIOS(CONCATENAR(SI(C111!$C$5=G$2;C111!$B$1 & " "; "")SI(C121!$C$5=G$2;C121!$B$1 & " "; "")SI(C122!$C$5=G$2;C122!$B$1 & " "; "")SI(C211!$C$5=G$2;C211!$B$1 & " "; "")SI(C212!$C$5=G$2;C212!$B$1 & " "; "")SI(C311!$C$5=G$2;C311!$B$1 & " "; "")SI(C312!$C$5=G$2;C312!$B$1 & " "; "")SI(C411!$C$5=G$2;C411!$B$1 & " "; "")SI(C412!$C$5=G$2;C412!$B$1 & " "; "")SI(D111!$C$5=G$2;D111!$B$1 & " "; "")SI(D211!$C$5=G$2;D211!$B$1 & " "; "")SI(D311!$C$5=G$2;D311!$B$1 & " "; "")SI(D411!$C$5=G$2;D411!$B$1 & " "; "")SI(M111!$C$5=G$2;M111!$B$1 & " "; "")SI(M211!$C$5=G$2;M211!$B$1 & " "; "")SI(M311!$C$5=G$2;M311!$B$1 & " "; "")SI(M411!$C$5=G$2;M411!$B$1 & " "; ""))); " "; ",") | H11: =SUSTITUIR(ESPACIOS(CONCATENAR(SI(C111!$C$5=H$2;C111!$B$1 & " "; "")SI(C121!$C$5=H$2;C121!$B$1 & " "; "")SI(C122!$C$5=H$2;C122!$B$1 & " "; "")SI(C211!$C$5=H$2;C211!$B$1 & " "; "")SI(C212!$C$5=H$2;C212!$B$1 & " "; "")SI(C311!$C$5=H$2;C311!$B$1 & " "; "")SI(C312!$C$5=H$2;C312!$B$1 & " "; "")SI(C411!$C$5=H$2;C411!$B$1 & " "; "")SI(C412!$C$5=H$2;C412!$B$1 & " "; "")SI(D111!$C$5=H$2;D111!$B$1 & " "; "")SI(D211!$C$5=H$2;D211!$B$1 & " "; "")SI(D311!$C$5=H$2;D311!$B$1 & " "; "")SI(D411!$C$5=H$2;D411!$B$1 & " "; "")SI(M111!$C$5=H$2;M111!$B$1 & " "; "")SI(M211!$C$5=H$2;M211!$B$1 & " "; "")SI(M311!$C$5=H$2;M311!$B$1 & " "; "")SI(M411!$C$5=H$2;M411!$B$1 & " "; ""))); " "; ",") | I11: =SUSTITUIR(ESPACIOS(CONCATENAR(SI(C111!$C$5=I$2;C111!$B$1 & " "; "")SI(C121!$C$5=I$2;C121!$B$1 & " "; "")SI(C122!$C$5=I$2;C122!$B$1 & " "; "")SI(C211!$C$5=I$2;C211!$B$1 & " "; "")SI(C212!$C$5=I$2;C212!$B$1 & " "; "")SI(C311!$C$5=I$2;C311!$B$1 & " "; "")SI(C312!$C$5=I$2;C312!$B$1 & " "; "")SI(C411!$C$5=I$2;C411!$B$1 & " "; "")SI(C412!$C$5=I$2;C412!$B$1 & " "; "")SI(D111!$C$5=I$2;D111!$B$1 & " "; "")SI(D211!$C$5=I$2;D211!$B$1 & " "; "")SI(D311!$C$5=I$2;D311!$B$1 & " "; "")SI(D411!$C$5=I$2;D411!$B$1 & " "; "")SI(M111!$C$5=I$2;M111!$B$1 & " "; "")SI(M211!$C$5=I$2;M211!$B$1 & " "; "")SI(M311!$C$5=I$2;M311!$B$1 & " "; "")SI(M411!$C$5=I$2;M411!$B$1 & " "; ""))); " "; ",") | J11: =SUSTITUIR(ESPACIOS(CONCATENAR(SI(C111!$C$5=J$2;C111!$B$1 & " "; "")SI(C121!$C$5=J$2;C121!$B$1 & " "; "")SI(C122!$C$5=J$2;C122!$B$1 & " "; "")SI(C211!$C$5=J$2;C211!$B$1 & " "; "")SI(C212!$C$5=J$2;C212!$B$1 & " "; "")SI(C311!$C$5=J$2;C311!$B$1 & " "; "")SI(C312!$C$5=J$2;C312!$B$1 & " "; "")SI(C411!$C$5=J$2;C411!$B$1 & " "; "")SI(C412!$C$5=J$2;C412!$B$1 & " "; "")SI(D111!$C$5=J$2;D111!$B$1 & " "; "")SI(D211!$C$5=J$2;D211!$B$1 & " "; "")SI(D311!$C$5=J$2;D311!$B$1 & " "; "")SI(D411!$C$5=J$2;D411!$B$1 & " "; "")SI(M111!$C$5=J$2;M111!$B$1 & " "; "")SI(M211!$C$5=J$2;M211!$B$1 & " "; "")SI(M311!$C$5=J$2;M311!$B$1 & " "; "")SI(M411!$C$5=J$2;M411!$B$1 & " "; ""))); " "; ",") | ... L11: =SUSTITUIR(ESPACIOS(CONCATENAR(SI(C111!$C$5=L$2;C111!$B$1 & " "; "")SI(C121!$C$5=L$2;C121!$B$1 & " "; "")SI(C122!$C$5=L$2;C122!$B$1 & " "; "")SI(C211!$C$5=L$2;C211!$B$1 & " "; "")SI(C212!$C$5=L$2;C212!$B$1 & " "; "")SI(C311!$C$5=L$2;C311!$B$1 & " "; "")SI(C312!$C$5=L$2;C312!$B$1 & " "; "")SI(C411!$C$5=L$2;C411!$B$1 & " "; "")SI(C412!$C$5=L$2;C412!$B$1 & " "; "")SI(D111!$C$5=L$2;D111!$B$1 & " "; "")SI(D211!$C$5=L$2;D211!$B$1 & " "; "")SI(D311!$C$5=L$2;D311!$B$1 & " "; "")SI(D411!$C$5=L$2;D411!$B$1 & " "; "")SI(M111!$C$5=L$2;M111!$B$1 & " "; "")SI(M211!$C$5=L$2;M211!$B$1 & " "; "")SI(M311!$C$5=L$2;M311!$B$1 & " "; "")SI(M411!$C$5=L$2;M411!$B$1 & " "; ""))); " "; ",")
A12: 3ro | C12: =SUSTITUIR(ESPACIOS(CONCATENAR(SI(C111!$C$5=C$2;C111!$B$1 & " "; "")SI(C121!$C$5=C$2;C121!$B$1 & " "; "")SI(C122!$C$5=C$2;C122!$B$1 & " "; "")SI(C211!$C$5=C$2;C211!$B$1 & " "; "")SI(C212!$C$5=C$2;C212!$B$1 & " "; "")SI(C311!$C$5=C$2;C311!$B$1 & " "; "")SI(C312!$C$5=C$2;C312!$B$1 & " "; "")SI(C411!$C$5=C$2;C411!$B$1 & " "; "")SI(C412!$C$5=C$2;C412!$B$1 & " "; "")SI(D111!$C$5=C$2;D111!$B$1 & " "; "")SI(D211!$C$5=C$2;D211!$B$1 & " "; "")SI(D311!$C$5=C$2;D311!$B$1 & " "; "")SI(D411!$C$5=C$2;D411!$B$1 & " "; "")SI(M111!$C$5=C$2;M111!$B$1 & " "; "")SI(M211!$C$5=C$2;M211!$B$1 & " "; "")SI(M311!$C$5=C$2;M311!$B$1 & " "; "")SI(M411!$C$5=C$2;M411!$B$1 & " "; ""))); " "; ",") | D12: =SUSTITUIR(ESPACIOS(CONCATENAR(SI(C111!$C$5=D$2;C111!$B$1 & " "; "")SI(C121!$C$5=D$2;C121!$B$1 & " "; "")SI(C122!$C$5=D$2;C122!$B$1 & " "; "")SI(C211!$C$5=D$2;C211!$B$1 & " "; "")SI(C212!$C$5=D$2;C212!$B$1 & " "; "")SI(C311!$C$5=D$2;C311!$B$1 & " "; "")SI(C312!$C$5=D$2;C312!$B$1 & " "; "")SI(C411!$C$5=D$2;C411!$B$1 & " "; "")SI(C412!$C$5=D$2;C412!$B$1 & " "; "")SI(D111!$C$5=D$2;D111!$B$1 & " "; "")SI(D211!$C$5=D$2;D211!$B$1 & " "; "")SI(D311!$C$5=D$2;D311!$B$1 & " "; "")SI(D411!$C$5=D$2;D411!$B$1 & " "; "")SI(M111!$C$5=D$2;M111!$B$1 & " "; "")SI(M211!$C$5=D$2;M211!$B$1 & " "; "")SI(M311!$C$5=D$2;M311!$B$1 & " "; "")SI(M411!$C$5=D$2;M411!$B$1 & " "; ""))); " "; ",") | E12: =SUSTITUIR(ESPACIOS(CONCATENAR(SI(C111!$C$5=E$2;C111!$B$1 & " "; "")SI(C121!$C$5=E$2;C121!$B$1 & " "; "")SI(C122!$C$5=E$2;C122!$B$1 & " "; "")SI(C211!$C$5=E$2;C211!$B$1 & " "; "")SI(C212!$C$5=E$2;C212!$B$1 & " "; "")SI(C311!$C$5=E$2;C311!$B$1 & " "; "")SI(C312!$C$5=E$2;C312!$B$1 & " "; "")SI(C411!$C$5=E$2;C411!$B$1 & " "; "")SI(C412!$C$5=E$2;C412!$B$1 & " "; "")SI(D111!$C$5=E$2;D111!$B$1 & " "; "")SI(D211!$C$5=E$2;D211!$B$1 & " "; "")SI(D311!$C$5=E$2;D311!$B$1 & " "; "")SI(D411!$C$5=E$2;D411!$B$1 & " "; "")SI(M111!$C$5=E$2;M111!$B$1 & " "; "")SI(M211!$C$5=E$2;M211!$B$1 & " "; "")SI(M311!$C$5=E$2;M311!$B$1 & " "; "")SI(M411!$C$5=E$2;M411!$B$1 & " "; ""))); " "; ",") | F12: =SUSTITUIR(ESPACIOS(CONCATENAR(SI(C111!$C$5=F$2;C111!$B$1 & " "; "")SI(C121!$C$5=F$2;C121!$B$1 & " "; "")SI(C122!$C$5=F$2;C122!$B$1 & " "; "")SI(C211!$C$5=F$2;C211!$B$1 & " "; "")SI(C212!$C$5=F$2;C212!$B$1 & " "; "")SI(C311!$C$5=F$2;C311!$B$1 & " "; "")SI(C312!$C$5=F$2;C312!$B$1 & " "; "")SI(C411!$C$5=F$2;C411!$B$1 & " "; "")SI(C412!$C$5=F$2;C412!$B$1 & " "; "")SI(D111!$C$5=F$2;D111!$B$1 & " "; "")SI(D211!$C$5=F$2;D211!$B$1 & " "; "")SI(D311!$C$5=F$2;D311!$B$1 & " "; "")SI(D411!$C$5=F$2;D411!$B$1 & " "; "")SI(M111!$C$5=F$2;M111!$B$1 & " "; "")SI(M211!$C$5=F$2;M211!$B$1 & " "; "")SI(M311!$C$5=F$2;M311!$B$1 & " "; "")SI(M411!$C$5=F$2;M411!$B$1 & " "; ""))); " "; ",") | G12: =SUSTITUIR(ESPACIOS(CONCATENAR(SI(C111!$C$5=G$2;C111!$B$1 & " "; "")SI(C121!$C$5=G$2;C121!$B$1 & " "; "")SI(C122!$C$5=G$2;C122!$B$1 & " "; "")SI(C211!$C$5=G$2;C211!$B$1 & " "; "")SI(C212!$C$5=G$2;C212!$B$1 & " "; "")SI(C311!$C$5=G$2;C311!$B$1 & " "; "")SI(C312!$C$5=G$2;C312!$B$1 & " "; "")SI(C411!$C$5=G$2;C411!$B$1 & " "; "")SI(C412!$C$5=G$2;C412!$B$1 & " "; "")SI(D111!$C$5=G$2;D111!$B$1 & " "; "")SI(D211!$C$5=G$2;D211!$B$1 & " "; "")SI(D311!$C$5=G$2;D311!$B$1 & " "; "")SI(D411!$C$5=G$2;D411!$B$1 & " "; "")SI(M111!$C$5=G$2;M111!$B$1 & " "; "")SI(M211!$C$5=G$2;M211!$B$1 & " "; "")SI(M311!$C$5=G$2;M311!$B$1 & " "; "")SI(M411!$C$5=G$2;M411!$B$1 & " "; ""))); " "; ",") | H12: =SUSTITUIR(ESPACIOS(CONCATENAR(SI(C111!$C$5=H$2;C111!$B$1 & " "; "")SI(C121!$C$5=H$2;C121!$B$1 & " "; "")SI(C122!$C$5=H$2;C122!$B$1 & " "; "")SI(C211!$C$5=H$2;C211!$B$1 & " "; "")SI(C212!$C$5=H$2;C212!$B$1 & " "; "")SI(C311!$C$5=H$2;C311!$B$1 & " "; "")SI(C312!$C$5=H$2;C312!$B$1 & " "; "")SI(C411!$C$5=H$2;C411!$B$1 & " "; "")SI(C412!$C$5=H$2;C412!$B$1 & " "; "")SI(D111!$C$5=H$2;D111!$B$1 & " "; "")SI(D211!$C$5=H$2;D211!$B$1 & " "; "")SI(D311!$C$5=H$2;D311!$B$1 & " "; "")SI(D411!$C$5=H$2;D411!$B$1 & " "; "")SI(M111!$C$5=H$2;M111!$B$1 & " "; "")SI(M211!$C$5=H$2;M211!$B$1 & " "; "")SI(M311!$C$5=H$2;M311!$B$1 & " "; "")SI(M411!$C$5=H$2;M411!$B$1 & " "; ""))); " "; ",") | I12: =SUSTITUIR(ESPACIOS(CONCATENAR(SI(C111!$C$5=I$2;C111!$B$1 & " "; "")SI(C121!$C$5=I$2;C121!$B$1 & " "; "")SI(C122!$C$5=I$2;C122!$B$1 & " "; "")SI(C211!$C$5=I$2;C211!$B$1 & " "; "")SI(C212!$C$5=I$2;C212!$B$1 & " "; "")SI(C311!$C$5=I$2;C311!$B$1 & " "; "")SI(C312!$C$5=I$2;C312!$B$1 & " "; "")SI(C411!$C$5=I$2;C411!$B$1 & " "; "")SI(C412!$C$5=I$2;C412!$B$1 & " "; "")SI(D111!$C$5=I$2;D111!$B$1 & " "; "")SI(D211!$C$5=I$2;D211!$B$1 & " "; "")SI(D311!$C$5=I$2;D311!$B$1 & " "; "")SI(D411!$C$5=I$2;D411!$B$1 & " "; "")SI(M111!$C$5=I$2;M111!$B$1 & " "; "")SI(M211!$C$5=I$2;M211!$B$1 & " "; "")SI(M311!$C$5=I$2;M311!$B$1 & " "; "")SI(M411!$C$5=I$2;M411!$B$1 & " "; ""))); " "; ",") | J12: =SUSTITUIR(ESPACIOS(CONCATENAR(SI(C111!$C$5=J$2;C111!$B$1 & " "; "")SI(C121!$C$5=J$2;C121!$B$1 & " "; "")SI(C122!$C$5=J$2;C122!$B$1 & " "; "")SI(C211!$C$5=J$2;C211!$B$1 & " "; "")SI(C212!$C$5=J$2;C212!$B$1 & " "; "")SI(C311!$C$5=J$2;C311!$B$1 & " "; "")SI(C312!$C$5=J$2;C312!$B$1 & " "; "")SI(C411!$C$5=J$2;C411!$B$1 & " "; "")SI(C412!$C$5=J$2;C412!$B$1 & " "; "")SI(D111!$C$5=J$2;D111!$B$1 & " "; "")SI(D211!$C$5=J$2;D211!$B$1 & " "; "")SI(D311!$C$5=J$2;D311!$B$1 & " "; "")SI(D411!$C$5=J$2;D411!$B$1 & " "; "")SI(M111!$C$5=J$2;M111!$B$1 & " "; "")SI(M211!$C$5=J$2;M211!$B$1 & " "; "")SI(M311!$C$5=J$2;M311!$B$1 & " "; "")SI(M411!$C$5=J$2;M411!$B$1 & " "; ""))); " "; ",") | ... L12: =SUSTITUIR(ESPACIOS(CONCATENAR(SI(C111!$C$5=L$2;C111!$B$1 & " "; "")SI(C121!$C$5=L$2;C121!$B$1 & " "; "")SI(C122!$C$5=L$2;C122!$B$1 & " "; "")SI(C211!$C$5=L$2;C211!$B$1 & " "; "")SI(C212!$C$5=L$2;C212!$B$1 & " "; "")SI(C311!$C$5=L$2;C311!$B$1 & " "; "")SI(C312!$C$5=L$2;C312!$B$1 & " "; "")SI(C411!$C$5=L$2;C411!$B$1 & " "; "")SI(C412!$C$5=L$2;C412!$B$1 & " "; "")SI(D111!$C$5=L$2;D111!$B$1 & " "; "")SI(D211!$C$5=L$2;D211!$B$1 & " "; "")SI(D311!$C$5=L$2;D311!$B$1 & " "; "")SI(D411!$C$5=L$2;D411!$B$1 & " "; "")SI(M111!$C$5=L$2;M111!$B$1 & " "; "")SI(M211!$C$5=L$2;M211!$B$1 & " "; "")SI(M311!$C$5=L$2;M311!$B$1 & " "; "")SI(M411!$C$5=L$2;M411!$B$1 & " "; ""))); " "; ",")
