Workbook

Sheet D111
A1: Grupo | B1: D111
C3: Lunes | D3: Martes | E3: Miércoles | F3: Jueves | G3: Viernes | I3: Abrev | J3: Asignaturas | K3: Frec | L3: Faltan | M3: Asignadas | O3: Aulas
B4: Turno 1 | C4: F | D4: ICD | E4: AL | F4: AM I | G4: AL | I4: AL | J4: Álgebra Lineal | K4: 3 | L4: =K4-M4 | M4: =COUNTIF(C4:G22,I4) | O4: Aula 6*
C5: Aula 8 | D5: Aula 7 | E5: Aula 7* | F5: Aula 7* | G5: Aula 7* | I5: L | J5: Lógica | K5: 2 | L5: =K5-M5 | M5: =COUNTIF(C4:G22,I5) | O5: Aula 7
I6: IP | J6: Introducción a la Programación | K6: 2 | L6: =K6-M6 | M6: =COUNTIF(C4:G22,I6) | O6: Aula 7*
B7: Turno 2 | C7: L | D7: AL | E7: EF | F7: L | I7: AM I | J7: Análisis Matemático I | K7: 2 | L7: =K7-M7 | M7: =COUNTIF(C4:G22,I7) | O7: Aula 8
C8: Aula 6* | D8: Aula 6* | E8: SEDER | F8: Aula 7 | I8: ICD | J8: Introducción a la Ciencia de Datos | K8: 2 | L8: =K8-M8 | M8: =COUNTIF(C4:G22,I8) | O8: Lab
I9: F | J9: Filosofía | K9: 2 | L9: =K9-M9 | M9: =COUNTIF(C4:G22,I9) | N9: Total: | O9: =COUNTA(O4:O8)
B10: Turno 3 | C10: IP | D10: AM I | E10: AM I | F10: IP | I10: EF | J10: Educación Física I | K10: 2 | L10: =K10-M10 | M10: =COUNTIF(C4:G22,I10)
C11: Aula 7 | D11: Aula 6* | E11: Aula 7* | F11: Lab | L11: Total: | M11: =COUNTA(I4:I10)
L12: Σ Frec: | M12: =SUM(K4:K10)
B14: Turno 4
B17: Turno 5
B20: Turno 6
F23: Ocupados: | G23: =COUNTA(C4:G22)/3

Sheet D211
A1: Grupo | B1: D211
C3: Lunes | D3: Martes | E3: Miércoles | F3: Jueves | G3: Viernes | I3: Abrev | J3: Asignaturas | K3: Frec | L3: Faltan | M3: Asignadas | O3: Aulas
B4: Turno 1 | I4: MA | J4: Matemática y Aplicaciones | K4: 2 | L4: =K4-M4 | M4: =COUNTIF(C4:G22,I4) | O4: c 6
I5: Prb | J5: Probabilidades | K5: 2 | L5: =K5-M5 | M5: =COUNTIF(C4:G22,I5) | O5: c 7
I6: BD | J6: Bases de Datos | K6: 2 | L6: =K6-M6 | M6: =COUNTIF(C4:G22,I6) | N6: Total: | O6: =COUNTA(O4:O5)
B7: Turno 2 | I7: ED | J7: Estructura de Datos | K7: 2 | L7: =K7-M7 | M7: =COUNTIF(C4:G22,I7)
I8: VD | J8: Visualización de Datos | K8: 2 | L8: =K8-M8 | M8: =COUNTIF(C4:G22,I8)
I9: EP | J9: Economía Política | K9: 2 | L9: =K9-M9 | M9: =COUNTIF(C4:G22,I9)
B10: Turno 3 | I10: EF | J10: Educación Física III | K10: 2 | L10: =K10-M10 | M10: =COUNTIF(C4:G22,I10)
L11: Total: | M11: =COUNTA(I4:I10)
L12: Σ Frec: | M12: =SUM(K4:K10)
B14: Turno 4 | C14: ED | D14: BD | E14: MA (EDO) cp 6 (con | F14: BD
C15: c 7 | D15: c 7 | E15: C211 | F15: cp 7
B17: Turno 5 | C17: VD | D17: EP | E17: EP | F17: Prb
C18: c 7 | D18: c 7 | E18: c 7 | F18: cp 7
B20: Turno 6 | C20: MA | D20: Prb | E20: EF 4:45pm a 5:35pm | F20: ED
C21: c 6 | D21: c 7 | F21: cp 7
F23: Ocupados: | G23: =COUNTA(C4:G22)/3

Sheet D311
A1: Grupo | B1: D311
C3: Lunes | D3: Martes | E3: Miércoles | F3: Jueves | G3: Viernes | I3: Abrev | J3: Asignaturas | K3: Frec | L3: Faltan | M3: Asignadas | O3: Aulas
B4: Turno 1 | C4: AE2 | D4: RN | E4: TP 4 | I4: AE2 | J4: Análisis Estadístico II | K4: 2 | L4: =K4-M4 | M4: =COUNTIF(C4:G22,I4) | O4: c 2
C5: c 2 | D5: c 2 | I5: MDE | J5: Muestreo y Diseño de Experimentos | K5: 2 | L5: =K5-M5 | M5: =COUNTIF(C4:G22,I5) | O5: c 4
I6: RN | J6: Redes Neuronales | K6: 2 | L6: =K6-M6 | M6: =COUNTIF(C4:G22,I6) | O6: cp Lab2
B7: Turno 2 | C7: MDE | D7: PL | E7: MDE | F7: RN | I7: PL | J7: Procesamiento del Lenguaje | K7: 2 | L7: =K7-M7 | M7: =COUNTIF(C4:G22,I7) | N7: Total: | O7: =COUNTA(O4:O6)
C8: c 2 | D8: c 2 | E8: cp 2 | F8: cp Lab2 | I8: PGVD | J8: Procesamiento de Grandes Volúmenes de Datos | K8: 2 | L8: =K8-M8 | M8: =COUNTIF(C4:G22,I8)
I9: TP | J9: Teoría Política | K9: 2 | L9: =K9-M9 | M9: =COUNTIF(C4:G22,I9)
B10: Turno 3 | C10: PGVD | D10: TP | E10: AE2 | F10: PGVD | L10: Total: | M10: =COUNTA(I4:I9)
C11: c 2 | D11: c 4 | E11: cp Lab2 | F11: cp 7 | L11: Σ Frec: | M11: =SUM(K4:K9)
B14: Turno 4
B17: Turno 5
B20: Turno 6
F23: Ocupados: | G23: =COUNTA(C4:G22)/3

Sheet D411
A1: Grupo | B1: D411
C3: Lunes | D3: Martes | E3: Miércoles | F3: Jueves | G3: Viernes | I3: Abrev | J3: Asignaturas | K3: Frec | L3: Faltan | M3: Asignadas | O3: Aulas
B4: Turno 1 | D4: EIA | F4: SN | I4: IN | J4: Inteligencia de Negocios | K4: 2 | L4: =K4-M4 | M4: =COUNTIF(C4:G22,I4)
C5: CP 2 | D5: 2 | E5: CP 2 | F5: C4 | I5: EIA | J5: Elementos de Inteligencia Artificial | K5: 2 | L5: =K5-M5 | M5: =COUNTIF(C4:G22,I5) | N5: Total: | O5: =COUNTA(O4:O4)
I6: CP | J6: Ciberseguridad y Privacidad | K6: 2 | L6: =K6-M6 | M6: =COUNTIF(C4:G22,I6)
B7: Turno 2 | C7: IN | D7: SN | E7: IN | F7: SN | I7: CO2 | J7: Curso Optativo II | K7: 2 | L7: =K7-M7 | M7: =COUNTIF(C4:G22,I7)
C8: 2 | D8: C4 | E8: 2 | F8: C4 | I8: ECTS | J8: Estudios de Ciencia, Tecnología y Sociedad | K8: 2 | L8: =K8-M8 | M8: =COUNTIF(C4:G22,I8)
I9: SN/DN | J9: Seguridad Nacional / Defensa Nacional | K9: 2 | L9: =K9-M9 | M9: =COUNTIF(C4:G22,I9)
B10: Turno 3 | C10: ECTS 9 (con | D10: CO | E10: EIA 2 | L10: Total: | M10: =COUNTA(I4:I9)
C11: C4 | D11: 2 | L11: Σ Frec: | M11: =SUM(K4:K9)
B14: Turno 4
B17: Turno 5
B20: Turno 6
F23: Ocupados: | G23: =COUNTA(C4:G22)/3

Sheet C111
A1: Grupo | B1: C111
C3: Lunes | D3: Martes | E3: Miércoles | F3: Jueves | G3: Viernes | I3: Abrev | J3: Asignaturas | K3: Frec | L3: Faltan | M3: Asignadas | O3: Aulas
B4: Turno 1 | C4: F | D4: A I | E4: AM I | F4: F | I4: A I | J4: Álgebra I | K4: 3 | L4: =K4-M4 | M4: =COUNTIF(C4:G22,I4) | O4: Aula 6
C5: Aula 6 | D5: Aula 6* | E5: Aula 6* | F5: Aula 6 | I5: L | J5: Lógica | K5: 2 | L5: =K5-M5 | M5: =COUNTIF(C4:G22,I5) | O5: Aula 6*
I6: P | J6: Programación | K6: 3 | L6: =K6-M6 | M6: =COUNTIF(C4:G22,I6) | O6: Lab
B7: Turno 2 | C7: L | D7: A I | E7: EF | F7: L | G7: A I | I7: AM I | J7: Análisis Matemático I | K7: 2 | L7: =K7-M7 | M7: =COUNTIF(C4:G22,I7) | N7: Total: | O7: =COUNTA(O4:O6)
C8: Aula 6* | D8: Aula 6* | E8: SEDER | F8: Aula 6* | G8: Aula 6* | I8: F | J8: Filosofía | K8: 2 | L8: =K8-M8 | M8: =COUNTIF(C4:G22,I8)
I9: EF | J9: Educación Física I | K9: 2 | L9: =K9-M9 | M9: =COUNTIF(C4:G22,I9)
B10: Turno 3 | C10: P | D10: AM I | E10: AM I | F10: P | G10: P | L10: Total: | M10: =COUNTA(I4:I9)
C11: Aula 6 | D11: Aula 6* | E11: Aula 6* | F11: Aula 6 | G11: Lab | L11: Σ Frec: | M11: =SUM(K4:K9)
B14: Turno 4
B17: Turno 5
B20: Turno 6
F23: Ocupados: | G23: =COUNTA(C4:G22)/3

Sheet C121
A1: Grupo | B1: C121
C3: Lunes | D3: Martes | E3: Miércoles | F3: Jueves | G3: Viernes | I3: Abrev | J3: Asignaturas | K3: Frec | L3: Faltan | M3: Asignadas | O3: Aulas
B4: Turno 1 | C4: P | D4: A I | E4: AM I | F4: P | G4: A I | I4: A I | J4: Álgebra I | K4: 3 | L4: =K4-M4 | M4: =COUNTIF(C4:G22,I4) | O4: Aula 5
C5: Aula 5 | D5: Aula 5 | E5: Aula 5 | F5: Aula 5 | G5: Aula 5 | I5: L | J5: Lógica | K5: 2 | L5: =K5-M5 | M5: =COUNTIF(C4:G22,I5) | N5: Total: | O5: =COUNTA(O4:O4)
I6: P | J6: Programación | K6: 3 | L6: =K6-M6 | M6: =COUNTIF(C4:G22,I6)
B7: Turno 2 | C7: F | D7: AM I | E7: EF | F7: L | G7: P | I7: AM I | J7: Análisis Matemático I | K7: 2 | L7: =K7-M7 | M7: =COUNTIF(C4:G22,I7)
C8: Aula 5 | D8: Aula 5 | E8: SEDER | F8: Aula 5 | G8: Lab | I8: F | J8: Filosofía | K8: 2 | L8: =K8-M8 | M8: =COUNTIF(C4:G22,I8)
I9: EF | J9: Educación Física I | K9: 2 | L9: =K9-M9 | M9: =COUNTIF(C4:G22,I9)
B10: Turno 3 | C10: L | D10: A I | E10: AM I | F10: F | L10: Total: | M10: =COUNTA(I4:I9)
C11: Aula 5 | D11: Aula 5 | E11: Aula 5 | F11: Aula 5 | L11: Σ Frec: | M11: =SUM(K4:K9)
B14: Turno 4
B17: Turno 5
B20: Turno 6
F23: Ocupados: | G23: =COUNTA(C4:G22)/3

Sheet C122
A1: Grupo | B1: C122
C3: Lunes | D3: Martes | E3: Miércoles | F3: Jueves | G3: Viernes | I3: Abrev | J3: Asignaturas | K3: Frec | L3: Faltan | M3: Asignadas | O3: Aulas
B4: Turno 1 | C4: P | D4: A I | E4: AM I | F4: L | G4: P | I4: A I | J4: Álgebra I | K4: 3 | L4: =K4-M4 | M4: =COUNTIF(C4:G22,I4) | O4: Aula 1
C5: Aula 5 | D5: Aula 5 | E5: Aula 1 | F5: Aula 1 | G5: Lab | I5: L | J5: Lógica | K5: 2 | L5: =K5-M5 | M5: =COUNTIF(C4:G22,I5) | O5: Aula 5
I6: P | J6: Programación | K6: 3 | L6: =K6-M6 | M6: =COUNTIF(C4:G22,I6) | O6: Lab
B7: Turno 2 | C7: F | D7: AM I | E7: EF | F7: AM I | G7: A I | I7: AM I | J7: Análisis Matemático I | K7: 2 | L7: =K7-M7 | M7: =COUNTIF(C4:G22,I7) | N7: Total: | O7: =COUNTA(O4:O6)
C8: Aula 5 | D8: Aula 5 | E8: SEDER | F8: Aula 1 | G8: Aula 1 | I8: F | J8: Filosofía | K8: 2 | L8: =K8-M8 | M8: =COUNTIF(C4:G22,I8)
I9: EF | J9: Educación Física I | K9: 2 | L9: =K9-M9 | M9: =COUNTIF(C4:G22,I9)
B10: Turno 3 | C10: L | D10: A I | E10: P | F10: F | L10: Total: | M10: =COUNTA(I4:I9)
C11: Aula 5 | D11: Aula 1 | E11: Aula 1 | F11: Aula 5 | L11: Σ Frec: | M11: =SUM(K4:K9)
B14: Turno 4
B17: Turno 5
B20: Turno 6
F23: Ocupados: | G23: =COUNTA(C4:G22)/3

Sheet C211
A1: Grupo | B1: C211
C3: Lunes | D3: Martes | E3: Miércoles | F3: Jueves | G3: Viernes | I3: Abrev | J3: Asignaturas | K3: Frec | L3: Faltan | M3: Asignadas | O3: Aulas
B4: Turno 1 | I4: EDA | J4: Estructuras de Datos y Algoritmos I | K4: 2 | L4: =K4-M4 | M4: =COUNTIF(C4:G22,I4) | O4: c 6
I5: MD | J5: Matemática Discreta I | K5: 2 | L5: =K5-M5 | M5: =COUNTIF(C4:G22,I5) | N5: Total: | O5: =COUNTA(O4:O4)
I6: AC | J6: Arquitectura de computadoras | K6: 2 | L6: =K6-M6 | M6: =COUNTIF(C4:G22,I6)
B7: Turno 2 | I7: EDO | J7: Ecuaciones Diferenciales Ordinarias | K7: 2 | L7: =K7-M7 | M7: =COUNTIF(C4:G22,I7)
I8: MN | J8: Matemática Numérica | K8: 2 | L8: =K8-M8 | M8: =COUNTIF(C4:G22,I8)
I9: TP | J9: Teoría Política | K9: 2 | L9: =K9-M9 | M9: =COUNTIF(C4:G22,I9)
B10: Turno 3 | I10: EF3 | J10: Educación Física III | K10: 2 | L10: =K10-M10 | M10: =COUNTIF(C4:G22,I10)
L11: Total: | M11: =COUNTA(I4:I10)
L12: Σ Frec: | M12: =SUM(K4:K10)
B14: Turno 4 | C14: EDA I | D14: MD | E14: EDO | F14: MN | G14: AC
C15: c 6 | D15: c6 | E15: cp 6 | F15: cp 6 | G15: lab
B17: Turno 5 | C17: TP | D17: MN | E17: EDA I | F17: TP | G17: MD
C18: c 6 | D18: c 6 | E18: cp 6 | F18: c 6 | G18: cp 6
B20: Turno 6 | C20: EDO | D20: AC | E20: EF 4:45pm a 5:35pm
C21: c 6 | D21: c 6
F23: Ocupados: | G23: =COUNTA(C4:G22)/3

Sheet C212
A1: Grupo | B1: C212
C3: Lunes | D3: Martes | E3: Miércoles | F3: Jueves | G3: Viernes | I3: Abrev | J3: Asignaturas | K3: Frec | L3: Faltan | M3: Asignadas | O3: Aulas
B4: Turno 1 | I4: EDA | J4: Estructuras de Datos y Algoritmos I | K4: 2 | L4: =K4-M4 | M4: =COUNTIF(C4:G22,I4) | O4: c 6
I5: MD | J5: Matemática Discreta I | K5: 2 | L5: =K5-M5 | M5: =COUNTIF(C4:G22,I5) | N5: Total: | O5: =COUNTA(O4:O4)
I6: AC | J6: Arquitectura de computadoras | K6: 2 | L6: =K6-M6 | M6: =COUNTIF(C4:G22,I6)
B7: Turno 2 | I7: EDO | J7: Ecuaciones Diferenciales Ordinarias | K7: 2 | L7: =K7-M7 | M7: =COUNTIF(C4:G22,I7)
I8: MN | J8: Matemática Numérica | K8: 2 | L8: =K8-M8 | M8: =COUNTIF(C4:G22,I8)
I9: TP | J9: Teoría Política | K9: 2 | L9: =K9-M9 | M9: =COUNTIF(C4:G22,I9)
B10: Turno 3 | I10: EF3 | J10: Educación Física III | K10: 2 | L10: =K10-M10 | M10: =COUNTIF(C4:G22,I10)
L11: Total: | M11: =COUNTA(I4:I10)
L12: Σ Frec: | M12: =SUM(K4:K10)
B14: Turno 4 | C14: EDA I | D14: MD | E14: EDO I | F14: MN | G14: AC
C15: c 6 | D15: c6 | E15: cp 5 | F15: cp 5 | G15: lab
B17: Turno 5 | C17: TP | D17: MN | E17: EDA I | F17: TP | G17: MD
C18: c 6 | D18: c 6 | E18: cp 5 | F18: c 6 | G18: cp 5
B20: Turno 6 | C20: EDO | D20: AC | E20: EF 4:45pm a 5:35pm
C21: c 6 | D21: c 6
F23: Ocupados: | G23: =COUNTA(C4:G22)/3

Sheet C311
A1: Grupo | B1: C311
C3: Lunes | D3: Martes | E3: Miércoles | F3: Jueves | G3: Viernes | I3: Abrev | J3: Asignaturas | K3: Frec | L3: Faltan | M3: Asignadas | O3: Aulas
B4: Turno 1 | C4: BD2 | D4: Est | E4: BD2 cp | F4: MO | I4: RC | J4: Redes de Computadoras | K4: 2 | L4: =K4-M4 | M4: =COUNTIF(C4:G22,I4) | O4: Aula 9
C5: Aula 9 | D5: Aula 9 | E5: Aula 9 | F5: Aula 9 | I5: IS | J5: Ingeniería de Software | K5: 2 | L5: =K5-M5 | M5: =COUNTIF(C4:G22,I5) | N5: Total: | O5: =COUNTA(O4:O4)
I6: MO | J6: Modelos de Optimización | K6: 2 | L6: =K6-M6 | M6: =COUNTIF(C4:G22,I6)
B7: Turno 2 | C7: IS c | D7: PD c | E7: IS c | F7: PD cp | I7: BD2 | J7: Bases de Datos II | K7: 2 | L7: =K7-M7 | M7: =COUNTIF(C4:G22,I7)
C8: Aula 9 | D8: Aula 9 | E8: Aula 9 | F8: Aula 9 | I8: PD | J8: Programación Declarativa | K8: 2 | L8: =K8-M8 | M8: =COUNTIF(C4:G22,I8)
I9: Est | J9: Estadística | K9: 2 | L9: =K9-M9 | M9: =COUNTIF(C4:G22,I9)
B10: Turno 3 | C10: RC | D10: MO | E10: RC cp | F10: Est cp | L10: Total: | M10: =COUNTA(I4:I9)
C11: Aula 9 | D11: Aula 9 | E11: Aula 9 | F11: Aula 9 | L11: Σ Frec: | M11: =SUM(K4:K9)
B14: Turno 4
B17: Turno 5
B20: Turno 6
F23: Ocupados: | G23: =COUNTA(C4:G22)/3

Sheet C312
A1: Grupo | B1: C312
C3: Lunes | D3: Martes | E3: Miércoles | F3: Jueves | G3: Viernes | I3: Abrev | J3: Asignaturas | K3: Frec | L3: Faltan | M3: Asignadas | O3: Aulas
B4: Turno 1 | C4: BD2 | D4: Est | E4: BD2 cp | F4: PD cp | I4: RC | J4: Redes de Computadoras | K4: 2 | L4: =K4-M4 | M4: =COUNTIF(C4:G22,I4) | O4: Aula 3
C5: Aula 9 | D5: Aula 9 | E5: Aula 3 | F5: Aula 3 | I5: IS | J5: Ingeniería de Software | K5: 2 | L5: =K5-M5 | M5: =COUNTIF(C4:G22,I5) | O5: Aula 9
I6: MO | J6: Modelos de Optimización | K6: 2 | L6: =K6-M6 | M6: =COUNTIF(C4:G22,I6) | N6: Total: | O6: =COUNTA(O4:O5)
B7: Turno 2 | C7: IS c | D7: PD c | E7: IS c | F7: MO | I7: BD2 | J7: Bases de Datos II | K7: 2 | L7: =K7-M7 | M7: =COUNTIF(C4:G22,I7)
C8: Aula 9 | D8: Aula 9 | E8: Aula 3 | F8: Aula 3 | I8: PD | J8: Programación Declarativa | K8: 2 | L8: =K8-M8 | M8: =COUNTIF(C4:G22,I8)
I9: Est | J9: Estadística | K9: 2 | L9: =K9-M9 | M9: =COUNTIF(C4:G22,I9)
B10: Turno 3 | C10: RC | D10: MO | E10: RC cp | F10: Est cp | L10: Total: | M10: =COUNTA(I4:I9)
C11: Aula 9 | D11: Aula 9 | E11: Aula 3 | F11: Aula 3 | L11: Σ Frec: | M11: =SUM(K4:K9)
B14: Turno 4
B17: Turno 5
B20: Turno 6
F23: Ocupados: | G23: =COUNTA(C4:G22)/3

Sheet C411
A1: Grupo | B1: C411
C3: Lunes | D3: Martes | E3: Miércoles | F3: Jueves | G3: Viernes | I3: Abrev | J3: Asignaturas | K3: Frec | L3: Faltan | M3: Asignadas | O3: Aulas
B4: Turno 1 | I4: AM | J4: Aprendizaje de Máquinas | K4: 2 | L4: =K4-M4 | M4: =COUNTIF(C4:G22,I4)
I5: DAA | J5: Diseño y Análisis de Algoritmos | K5: 2 | L5: =K5-M5 | M5: =COUNTIF(C4:G22,I5) | N5: Total: | O5: =COUNTA(O4:O4)
I6: SD | J6: Sistemas Distribuidos | K6: 2 | L6: =K6-M6 | M6: =COUNTIF(C4:G22,I6)
B7: Turno 2 | I7: AE | J7: Asignatura Electiva | K7: 2 | L7: =K7-M7 | M7: =COUNTIF(C4:G22,I7)
I8: ECTS | J8: Estudios de Ciencia, Tecnología y Sociedad | K8: 2 | L8: =K8-M8 | M8: =COUNTIF(C4:G22,I8)
I9: SN/DN | J9: Seguridad Nacional / Defensa Nacionaol | K9: 2 | L9: =K9-M9 | M9: =COUNTIF(C4:G22,I9)
B10: Turno 3 | L10: Total: | M10: =COUNTA(I4:I9)
L11: Σ Frec: | M11: =SUM(K4:K9)
B14: Turno 4 | C14: AM | D14: DAA | E14: DAA | F14: SN
C15: 9 | D15: 9 | E15: 9
B17: Turno 5 | C17: SD 9 | D17: SN | E17: AM | F17: SN
E18: 9
B20: Turno 6 | C20: ECTS 9 | D20: AE | E20: SD
D21: 9 | E21: 9
F23: Ocupados: | G23: =COUNTA(C4:G22)/3

Sheet C412
A1: Grupo | B1: C412
C3: Lunes | D3: Martes | E3: Miércoles | F3: Jueves | G3: Viernes | I3: Abrev | J3: Asignaturas | K3: Frec | L3: Faltan | M3: Asignadas | O3: Aulas
B4: Turno 1 | I4: AM | J4: Aprendizaje de Máquinas | K4: 2 | L4: =K4-M4 | M4: =COUNTIF(C4:G22,I4)
I5: DAA | J5: Diseño y Análisis de Algoritmos | K5: 2 | L5: =K5-M5 | M5: =COUNTIF(C4:G22,I5) | N5: Total: | O5: =COUNTA(O4:O4)
I6: SD | J6: Sistemas Distribuidos | K6: 2 | L6: =K6-M6 | M6: =COUNTIF(C4:G22,I6)
B7: Turno 2 | I7: AE | J7: Asignatura Electiva | K7: 2 | L7: =K7-M7 | M7: =COUNTIF(C4:G22,I7)
I8: ECTS | J8: Estudios de Ciencia, Tecnología y Sociedad | K8: 2 | L8: =K8-M8 | M8: =COUNTIF(C4:G22,I8)
I9: SN/DN | J9: Seguridad Nacional / Defensa Nacionaol | K9: 2 | L9: =K9-M9 | M9: =COUNTIF(C4:G22,I9)
B10: Turno 3 | L10: Total: | M10: =COUNTA(I4:I9)
L11: Σ Frec: | M11: =SUM(K4:K9)
B14: Turno 4 | C14: AM | D14: DAA | E14: DAA | F14: SN
C15: 9 | D15: 9 | E15: 9
B17: Turno 5 | C17: SD 9 | D17: SN | E17: AM | F17: SN
E18: 1
B20: Turno 6 | C20: ECTS 9 | D20: AE | E20: SD
E21: 9
F23: Ocupados: | G23: =COUNTA(C4:G22)/3

Sheet M111
A1: Grupo | B1: M111
C3: Lunes | D3: Martes | E3: Miércoles | F3: Jueves | G3: Viernes | I3: Abrev | J3: Asignaturas | K3: Frec | L3: Faltan | M3: Asignadas | O3: Aulas
B4: Turno 1 | C4: F | D4: IM | E4: IAM | F4: IA | G4: IA | I4: IAM | J4: Introducción al Análisis Matemático | K4: 3 | L4: =K4-M4 | M4: =COUNTIF(C4:G22,I4) | O4: Aula 8
C5: Aula 8 | D5: Aula 8 | E5: Aula 8 | F5: Aula 8 | G5: Aula 8 | I5: IA | J5: Introducción al Álgebra | K5: 3 | L5: =K5-M5 | M5: =COUNTIF(C4:G22,I5) | O5: PA Aula
I6: GA | J6: Geometría Analítica | K6: 2 | L6: =K6-M6 | M6: =COUNTIF(C4:G22,I6) | N6: Total: | O6: =COUNTA(O4:O5)
B7: Turno 2 | C7: PA | D7: IAM | E7: EF | F7: PA Aula | G7: IAM | I7: PA | J7: Programación y Algoritmos | K7: 2 | L7: =K7-M7 | M7: =COUNTIF(C4:G22,I7)
C8: Aula 8 | D8: Aula 8 | E8: SEDER | F8: Lab | G8: Aula 8 | I8: IM | J8: Introducción a la Matemática | K8: 2 | L8: =K8-M8 | M8: =COUNTIF(C4:G22,I8)
I9: F | J9: Filosofía | K9: 2 | L9: =K9-M9 | M9: =COUNTIF(C4:G22,I9)
B10: Turno 3 | C10: GA | D10: GA | E10: IA | F10: GA 8 | I10: EF | J10: Educación Física I | K10: 2 | L10: =K10-M10 | M10: =COUNTIF(C4:G22,I10)
C11: Aula 8 | D11: Aula 8 | E11: Aula 8 | L11: Total: | M11: =COUNTA(I4:I10)
L12: Σ Frec: | M12: =SUM(K4:K10)
B14: Turno 4
B17: Turno 5
B20: Turno 6
F23: Ocupados: | G23: =COUNTA(C4:G22)/3

Sheet M211
A1: Grupo | B1: M211
C3: Lunes | D3: Martes | E3: Miércoles | F3: Jueves | G3: Viernes | I3: Abrev | J3: Asignaturas | K3: Frec | L3: Faltan | M3: Asignadas | O3: Aulas
B4: Turno 1 | I4: FVV | J4: Funciones de Varias Variables | K4: 4 | L4: =K4-M4 | M4: =COUNTIF(C4:G22,I4) | O4: c 3
I5: CAL | J5: Complementos de Álgebra Lineal | K5: 3 | L5: =K5-M5 | M5: =COUNTIF(C4:G22,I5) | N5: Total: | O5: =COUNTA(O4:O4)
I6: SP2 | J6: Seminario de Problemas II | K6: 2 | L6: =K6-M6 | M6: =COUNTIF(C4:G22,I6)
B7: Turno 2 | I7: AE | J7: Asignatura Electiva I | K7: 2 | L7: =K7-M7 | M7: =COUNTIF(C4:G22,I7)
I8: EP | J8: Economía Política | K8: 2 | L8: =K8-M8 | M8: =COUNTIF(C4:G22,I8)
I9: EF | J9: Educación Física III | K9: 2 | L9: =K9-M9 | M9: =COUNTIF(C4:G22,I9)
B10: Turno 3 | C10: CAL | D10: CAL | L10: Total: | M10: =COUNTA(I4:I9)
C11: c 3 | D11: c 3 | L11: Σ Frec: | M11: =SUM(K4:K9)
B14: Turno 4 | C14: FVV | D14: FVV | E14: FVV | F14: CAL
C15: c 3 | D15: c 3 | E15: cp 3 | F15: cp 3
B17: Turno 5 | C17: EP | D17: EP | E17: FVV
C18: c 7 | D18: c 7 | E18: cp 3
B20: Turno 6 | C20: EF 4:45pm a 5:35pm | D20: SP
D21: 2
F23: Ocupados: | G23: =COUNTA(C4:G22)/3

Sheet M311
A1: Grupo | B1: M311
C3: Lunes | D3: Martes | E3: Miércoles | F3: Jueves | G3: Viernes | I3: Abrev | J3: Asignaturas | K3: Frec | L3: Faltan | M3: Asignadas | O3: Aulas
B4: Turno 1 | C4: MN | D4: EDO | E4: MN | F4: FV | G4: FVC | I4: FVC | J4: Funciones de variable Compleja | K4: 2 | L4: =K4-M4 | M4: =COUNTIF(C4:G22,I4) | O4: Aula 4
C5: Aula 4 | D5: Aula 4 | E5: 4 | F5: C 4 | G5: Aula 4 | I5: IE | J5: Inferencia Estadística | K5: 3 | L5: =K5-M5 | M5: =COUNTIF(C4:G22,I5) | N5: Total: | O5: =COUNTA(O4:O4)
I6: EDO | J6: Ecuaciones Diferenciales Ordinarias | K6: 3 | L6: =K6-M6 | M6: =COUNTIF(C4:G22,I6)
B7: Turno 2 | C7: FVC | D7: OM | E7: EDO | F7: IE | G7: EDO | I7: MN | J7: Matemática Numérica | K7: 2 | L7: =K7-M7 | M7: =COUNTIF(C4:G22,I7)
C8: Aula 4 | D8: Aula 4 | E8: Aula 4 | F8: Aula 4 | G8: Aula 4 | I8: OM | J8: Optimización Matemática I | K8: 2 | L8: =K8-M8 | M8: =COUNTIF(C4:G22,I8)
I9: TP | J9: Teoría Política | K9: 2 | L9: =K9-M9 | M9: =COUNTIF(C4:G22,I9)
B10: Turno 3 | C10: IE | D10: TP | E10: IE | F10: OM | L10: Total: | M10: =COUNTA(I4:I9)
C11: Aula 4 | D11: Aula 4 | E11: Aula 4 | F11: Aula 4 | L11: Σ Frec: | M11: =SUM(K4:K9)
B14: Turno 4
B17: Turno 5
B20: Turno 6
F23: Ocupados: | G23: =COUNTA(C4:G22)/3

Sheet M411
A1: Grupo | B1: M411
C3: Lunes | D3: Martes | E3: Miércoles | F3: Jueves | G3: Viernes | I3: Abrev | J3: Asignaturas | K3: Frec | L3: Faltan | M3: Asignadas | O3: Aulas
B4: Turno 1 | I4: MI | J4: Medida e Integración | K4: 2 | L4: =K4-M4 | M4: =COUNTIF(C4:G22,I4)
I5: GD | J5: Geometría Diferencial | K5: 2 | L5: =K5-M5 | M5: =COUNTIF(C4:G22,I5) | N5: Total: | O5: =COUNTA(O4:O4)
I6: HM | J6: Historia de la Matemática | K6: 2 | L6: =K6-M6 | M6: =COUNTIF(C4:G22,I6)
B7: Turno 2 | I7: ECTS | J7: Estudios de Ciencia, Tecnología y Sociedad | K7: 2 | L7: =K7-M7 | M7: =COUNTIF(C4:G22,I7)
I8: AO2 | J8: Asignatura Optativa II | K8: 2 | L8: =K8-M8 | M8: =COUNTIF(C4:G22,I8)
I9: AO3 | J9: Asignatura Optativa III | K9: 2 | L9: =K9-M9 | M9: =COUNTIF(C4:G22,I9)
B10: Turno 3 | L10: Total: | M10: =COUNTA(I4:I9)
L11: Σ Frec: | M11: =SUM(K4:K9)
B14: Turno 4 | C14: GD | D14: HM | E14: MI | F14: AO
C15: 4 | D15: 4 | E15: 4 | F15: 2
B17: Turno 5 | C17: MI | D17: HM | E17: GD | F17: AO
C18: 4 | D18: 4 | E18: 4 | F18: 3
B20: Turno 6 | C20: ECTS 9 (Con | D20: GD
C21: C4 | D21: 4
F23: Ocupados: | G23: =COUNTA(C4:G22)/3

Sheet Aulas
C2: 1 | D2: 2 | E2: 3 | F2: 4 | G2: 5 | H2: 6 | I2: 7 | J2: 8 | K2: 9 | L2: Lab
B3: Lunes | C3: Aula 1 | D3: Aula 2 | E3: Aula 3 | F3: Aula 4 | G3: Aula 5 | H3: Aula 6 | I3: Aula 7 | J3: Aula 8 | K3: Aula 9 | L3: Lab
B4: 1ro | C4: =SUBSTITUTE(TRIM((IF(D111!$C$5=C$3,D111!$B$1 & " ", "") & IF(D211!$C$5=C$3,D211!$B$1 & " ", "") & IF(D311!$C$5=C$3,D311!$B$1 & " ", "") & IF(D411!$C$5=C$3,D411!$B$1 & " ", "") & IF(C111!$C$5=C$3,C111!$B$1 & " ", "") & IF(C121!$C$5=C$3,C121!$B$1 & " ", "") & IF(C122!$C$5=C$3,C122!$B$1 & " ", "") & IF(C211!$C$5=C$3,C211!$B$1 & " ", "") & IF(C212!$C$5=C$3,C212!$B$1 & " ", "") & IF(C311!$C$5=C$3,C311!$B$1 & " ", "") & IF(C312!$C$5=C$3,C312!$B$1 & " ", "") & IF(C411!$C$5=C$3,C411!$B$1 & " ", "") & IF(C412!$C$5=C$3,C412!$B$1 & " ", "") & IF(M111!$C$5=C$3,M111!$B$1 & " ", "") & IF(M211!$C$5=C$3,M211!$B$1 & " ", "") & IF(M311!$C$5=C$3,M311!$B$1 & " ", "") & IF(M411!$C$5=C$3,M411!$B$1 & " ", ""))), " ", ",") | D4: =SUBSTITUTE(TRIM((IF(D111!$C$5=D$3,D111!$B$1 & " ", "") & IF(D211!$C$5=D$3,D211!$B$1 & " ", "") & IF(D311!$C$5=D$3,D311!$B$1 & " ", "") & IF(D411!$C$5=D$3,D411!$B$1 & " ", "") & IF(C111!$C$5=D$3,C111!$B$1 & " ", "") & IF(C121!$C$5=D$3,C121!$B$1 & " ", "") & IF(C122!$C$5=D$3,C122!$B$1 & " ", "") & IF(C211!$C$5=D$3,C211!$B$1 & " ", "") & IF(C212!$C$5=D$3,C212!$B$1 & " ", "") & IF(C311!$C$5=D$3,C311!$B$1 & " ", "") & IF(C312!$C$5=D$3,C312!$B$1 & " ", "") & IF(C411!$C$5=D$3,C411!$B$1 & " ", "") & IF(C412!$C$5=D$3,C412!$B$1 & " ", "") & IF(M111!$C$5=D$3,M111!$B$1 & " ", "") & IF(M211!$C$5=D$3,M211!$B$1 & " ", "") & IF(M311!$C$5=D$3,M311!$B$1 & " ", "") & IF(M411!$C$5=D$3,M411!$B$1 & " ", ""))), " ", ",") | E4: =SUBSTITUTE(TRIM((IF(D111!$C$5=E$3,D111!$B$1 & " ", "") & IF(D211!$C$5=E$3,D211!$B$1 & " ", "") & IF(D311!$C$5=E$3,D311!$B$1 & " ", "") & IF(D411!$C$5=E$3,D411!$B$1 & " ", "") & IF(C111!$C$5=E$3,C111!$B$1 & " ", "") & IF(C121!$C$5=E$3,C121!$B$1 & " ", "") & IF(C122!$C$5=E$3,C122!$B$1 & " ", "") & IF(C211!$C$5=E$3,C211!$B$1 & " ", "") & IF(C212!$C$5=E$3,C212!$B$1 & " ", "") & IF(C311!$C$5=E$3,C311!$B$1 & " ", "") & IF(C312!$C$5=E$3,C312!$B$1 & " ", "") & IF(C411!$C$5=E$3,C411!$B$1 & " ", "") & IF(C412!$C$5=E$3,C412!$B$1 & " ", "") & IF(M111!$C$5=E$3,M111!$B$1 & " ", "") & IF(M211!$C$5=E$3,M211!$B$1 & " ", "") & IF(M311!$C$5=E$3,M311!$B$1 & " ", "") & IF(M411!$C$5=E$3,M411!$B$1 & " ", ""))), " ", ",") | F4: =SUBSTITUTE(TRIM((IF(D111!$C$5=F$3,D111!$B$1 & " ", "") & IF(D211!$C$5=F$3,D211!$B$1 & " ", "") & IF(D311!$C$5=F$3,D311!$B$1 & " ", "") & IF(D411!$C$5=F$3,D411!$B$1 & " ", "") & IF(C111!$C$5=F$3,C111!$B$1 & " ", "") & IF(C121!$C$5=F$3,C121!$B$1 & " ", "") & IF(C122!$C$5=F$3,C122!$B$1 & " ", "") & IF(C211!$C$5=F$3,C211!$B$1 & " ", "") & IF(C212!$C$5=F$3,C212!$B$1 & " ", "") & IF(C311!$C$5=F$3,C311!$B$1 & " ", "") & IF(C312!$C$5=F$3,C312!$B$1 & " ", "") & IF(C411!$C$5=F$3,C411!$B$1 & " ", "") & IF(C412!$C$5=F$3,C412!$B$1 & " ", "") & IF(M111!$C$5=F$3,M111!$B$1 & " ", "") & IF(M211!$C$5=F$3,M211!$B$1 & " ", "") & IF(M311!$C$5=F$3,M311!$B$1 & " ", "") & IF(M411!$C$5=F$3,M411!$B$1 & " ", ""))), " ", ",") | G4: =SUBSTITUTE(TRIM((IF(D111!$C$5=G$3,D111!$B$1 & " ", "") & IF(D211!$C$5=G$3,D211!$B$1 & " ", "") & IF(D311!$C$5=G$3,D311!$B$1 & " ", "") & IF(D411!$C$5=G$3,D411!$B$1 & " ", "") & IF(C111!$C$5=G$3,C111!$B$1 & " ", "") & IF(C121!$C$5=G$3,C121!$B$1 & " ", "") & IF(C122!$C$5=G$3,C122!$B$1 & " ", "") & IF(C211!$C$5=G$3,C211!$B$1 & " ", "") & IF(C212!$C$5=G$3,C212!$B$1 & " ", "") & IF(C311!$C$5=G$3,C311!$B$1 & " ", "") & IF(C312!$C$5=G$3,C312!$B$1 & " ", "") & IF(C411!$C$5=G$3,C411!$B$1 & " ", "") & IF(C412!$C$5=G$3,C412!$B$1 & " ", "") & IF(M111!$C$5=G$3,M111!$B$1 & " ", "") & IF(M211!$C$5=G$3,M211!$B$1 & " ", "") & IF(M311!$C$5=G$3,M311!$B$1 & " ", "") & IF(M411!$C$5=G$3,M411!$B$1 & " ", ""))), " ", ",") | H4: =SUBSTITUTE(TRIM((IF(D111!$C$5=H$3,D111!$B$1 & " ", "") & IF(D211!$C$5=H$3,D211!$B$1 & " ", "") & IF(D311!$C$5=H$3,D311!$B$1 & " ", "") & IF(D411!$C$5=H$3,D411!$B$1 & " ", "") & IF(C111!$C$5=H$3,C111!$B$1 & " ", "") & IF(C121!$C$5=H$3,C121!$B$1 & " ", "") & IF(C122!$C$5=H$3,C122!$B$1 & " ", "") & IF(C211!$C$5=H$3,C211!$B$1 & " ", "") & IF(C212!$C$5=H$3,C212!$B$1 & " ", "") & IF(C311!$C$5=H$3,C311!$B$1 & " ", "") & IF(C312!$C$5=H$3,C312!$B$1 & " ", "") & IF(C411!$C$5=H$3,C411!$B$1 & " ", "") & IF(C412!$C$5=H$3,C412!$B$1 & " ", "") & IF(M111!$C$5=H$3,M111!$B$1 & " ", "") & IF(M211!$C$5=H$3,M211!$B$1 & " ", "") & IF(M311!$C$5=H$3,M311!$B$1 & " ", "") & IF(M411!$C$5=H$3,M411!$B$1 & " ", ""))), " ", ",") | I4: =SUBSTITUTE(TRIM((IF(D111!$C$5=I$3,D111!$B$1 & " ", "") & IF(D211!$C$5=I$3,D211!$B$1 & " ", "") & IF(D311!$C$5=I$3,D311!$B$1 & " ", "") & IF(D411!$C$5=I$3,D411!$B$1 & " ", "") & IF(C111!$C$5=I$3,C111!$B$1 & " ", "") & IF(C121!$C$5=I$3,C121!$B$1 & " ", "") & IF(C122!$C$5=I$3,C122!$B$1 & " ", "") & IF(C211!$C$5=I$3,C211!$B$1 & " ", "") & IF(C212!$C$5=I$3,C212!$B$1 & " ", "") & IF(C311!$C$5=I$3,C311!$B$1 & " ", "") & IF(C312!$C$5=I$3,C312!$B$1 & " ", "") & IF(C411!$C$5=I$3,C411!$B$1 & " ", "") & IF(C412!$C$5=I$3,C412!$B$1 & " ", "") & IF(M111!$C$5=I$3,M111!$B$1 & " ", "") & IF(M211!$C$5=I$3,M211!$B$1 & " ", "") & IF(M311!$C$5=I$3,M311!$B$1 & " ", "") & IF(M411!$C$5=I$3,M411!$B$1 & " ", ""))), " ", ",") | J4: =SUBSTITUTE(TRIM((IF(D111!$C$5=J$3,D111!$B$1 & " ", "") & IF(D211!$C$5=J$3,D211!$B$1 & " ", "") & IF(D311!$C$5=J$3,D311!$B$1 & " ", "") & IF(D411!$C$5=J$3,D411!$B$1 & " ", "") & IF(C111!$C$5=J$3,C111!$B$1 & " ", "") & IF(C121!$C$5=J$3,C121!$B$1 & " ", "") & IF(C122!$C$5=J$3,C122!$B$1 & " ", "") & IF(C211!$C$5=J$3,C211!$B$1 & " ", "") & IF(C212!$C$5=J$3,C212!$B$1 & " ", "") & IF(C311!$C$5=J$3,C311!$B$1 & " ", "") & IF(C312!$C$5=J$3,C312!$B$1 & " ", "") & IF(C411!$C$5=J$3,C411!$B$1 & " ", "") & IF(C412!$C$5=J$3,C412!$B$1 & " ", "") & IF(M111!$C$5=J$3,M111!$B$1 & " ", "") & IF(M211!$C$5=J$3,M211!$B$1 & " ", "") & IF(M311!$C$5=J$3,M311!$B$1 & " ", "") & IF(M411!$C$5=J$3,M411!$B$1 & " ", ""))), " ", ",") | ... L4: =SUBSTITUTE(TRIM((IF(D111!$C$5=L$3,D111!$B$1 & " ", "") & IF(D211!$C$5=L$3,D211!$B$1 & " ", "") & IF(D311!$C$5=L$3,D311!$B$1 & " ", "") & IF(D411!$C$5=L$3,D411!$B$1 & " ", "") & IF(C111!$C$5=L$3,C111!$B$1 & " ", "") & IF(C121!$C$5=L$3,C121!$B$1 & " ", "") & IF(C122!$C$5=L$3,C122!$B$1 & " ", "") & IF(C211!$C$5=L$3,C211!$B$1 & " ", "") & IF(C212!$C$5=L$3,C212!$B$1 & " ", "") & IF(C311!$C$5=L$3,C311!$B$1 & " ", "") & IF(C312!$C$5=L$3,C312!$B$1 & " ", "") & IF(C411!$C$5=L$3,C411!$B$1 & " ", "") & IF(C412!$C$5=L$3,C412!$B$1 & " ", "") & IF(M111!$C$5=L$3,M111!$B$1 & " ", "") & IF(M211!$C$5=L$3,M211!$B$1 & " ", "") & IF(M311!$C$5=L$3,M311!$B$1 & " ", "") & IF(M411!$C$5=L$3,M411!$B$1 & " ", ""))), " ", ",")
B5: 2do | C5: =SUBSTITUTE(TRIM((IF(D111!$C$8=C$3,D111!$B$1 & " ", "") & IF(D211!$C$8=C$3,D211!$B$1 & " ", "") & IF(D311!$C$8=C$3,D311!$B$1 & " ", "") & IF(D411!$C$8=C$3,D411!$B$1 & " ", "") & IF(C111!$C$8=C$3,C111!$B$1 & " ", "") & IF(C121!$C$8=C$3,C121!$B$1 & " ", "") & IF(C122!$C$8=C$3,C122!$B$1 & " ", "") & IF(C211!$C$8=C$3,C211!$B$1 & " ", "") & IF(C212!$C$8=C$3,C212!$B$1 & " ", "") & IF(C311!$C$8=C$3,C311!$B$1 & " ", "") & IF(C312!$C$8=C$3,C312!$B$1 & " ", "") & IF(C411!$C$8=C$3,C411!$B$1 & " ", "") & IF(C412!$C$8=C$3,C412!$B$1 & " ", "") & IF(M111!$C$8=C$3,M111!$B$1 & " ", "") & IF(M211!$C$8=C$3,M211!$B$1 & " ", "") & IF(M311!$C$8=C$3,M311!$B$1 & " ", "") & IF(M411!$C$8=C$3,M411!$B$1 & " ", ""))), " ", ",") | D5: =SUBSTITUTE(TRIM((IF(D111!$C$8=D$3,D111!$B$1 & " ", "") & IF(D211!$C$8=D$3,D211!$B$1 & " ", "") & IF(D311!$C$8=D$3,D311!$B$1 & " ", "") & IF(D411!$C$8=D$3,D411!$B$1 & " ", "") & IF(C111!$C$8=D$3,C111!$B$1 & " ", "") & IF(C121!$C$8=D$3,C121!$B$1 & " ", "") & IF(C122!$C$8=D$3,C122!$B$1 & " ", "") & IF(C211!$C$8=D$3,C211!$B$1 & " ", "") & IF(C212!$C$8=D$3,C212!$B$1 & " ", "") & IF(C311!$C$8=D$3,C311!$B$1 & " ", "") & IF(C312!$C$8=D$3,C312!$B$1 & " ", "") & IF(C411!$C$8=D$3,C411!$B$1 & " ", "") & IF(C412!$C$8=D$3,C412!$B$1 & " ", "") & IF(M111!$C$8=D$3,M111!$B$1 & " ", "") & IF(M211!$C$8=D$3,M211!$B$1 & " ", "") & IF(M311!$C$8=D$3,M311!$B$1 & " ", "") & IF(M411!$C$8=D$3,M411!$B$1 & " ", ""))), " ", ",") | E5: =SUBSTITUTE(TRIM((IF(D111!$C$8=E$3,D111!$B$1 & " ", "") & IF(D211!$C$8=E$3,D211!$B$1 & " ", "") & IF(D311!$C$8=E$3,D311!$B$1 & " ", "") & IF(D411!$C$8=E$3,D411!$B$1 & " ", "") & IF(C111!$C$8=E$3,C111!$B$1 & " ", "") & IF(C121!$C$8=E$3,C121!$B$1 & " ", "") & IF(C122!$C$8=E$3,C122!$B$1 & " ", "") & IF(C211!$C$8=E$3,C211!$B$1 & " ", "") & IF(C212!$C$8=E$3,C212!$B$1 & " ", "") & IF(C311!$C$8=E$3,C311!$B$1 & " ", "") & IF(C312!$C$8=E$3,C312!$B$1 & " ", "") & IF(C411!$C$8=E$3,C411!$B$1 & " ", "") & IF(C412!$C$8=E$3,C412!$B$1 & " ", "") & IF(M111!$C$8=E$3,M111!$B$1 & " ", "") & IF(M211!$C$8=E$3,M211!$B$1 & " ", "") & IF(M311!$C$8=E$3,M311!$B$1 & " ", "") & IF(M411!$C$8=E$3,M411!$B$1 & " ", ""))), " ", ",") | F5: =SUBSTITUTE(TRIM((IF(D111!$C$8=F$3,D111!$B$1 & " ", "") & IF(D211!$C$8=F$3,D211!$B$1 & " ", "") & IF(D311!$C$8=F$3,D311!$B$1 & " ", "") & IF(D411!$C$8=F$3,D411!$B$1 & " ", "") & IF(C111!$C$8=F$3,C111!$B$1 & " ", "") & IF(C121!$C$8=F$3,C121!$B$1 & " ", "") & IF(C122!$C$8=F$3,C122!$B$1 & " ", "") & IF(C211!$C$8=F$3,C211!$B$1 & " ", "") & IF(C212!$C$8=F$3,C212!$B$1 & " ", "") & IF(C311!$C$8=F$3,C311!$B$1 & " ", "") & IF(C312!$C$8=F$3,C312!$B$1 & " ", "") & IF(C411!$C$8=F$3,C411!$B$1 & " ", "") & IF(C412!$C$8=F$3,C412!$B$1 & " ", "") & IF(M111!$C$8=F$3,M111!$B$1 & " ", "") & IF(M211!$C$8=F$3,M211!$B$1 & " ", "") & IF(M311!$C$8=F$3,M311!$B$1 & " ", "") & IF(M411!$C$8=F$3,M411!$B$1 & " ", ""))), " ", ",") | G5: =SUBSTITUTE(TRIM((IF(D111!$C$8=G$3,D111!$B$1 & " ", "") & IF(D211!$C$8=G$3,D211!$B$1 & " ", "") & IF(D311!$C$8=G$3,D311!$B$1 & " ", "") & IF(D411!$C$8=G$3,D411!$B$1 & " ", "") & IF(C111!$C$8=G$3,C111!$B$1 & " ", "") & IF(C121!$C$8=G$3,C121!$B$1 & " ", "") & IF(C122!$C$8=G$3,C122!$B$1 & " ", "") & IF(C211!$C$8=G$3,C211!$B$1 & " ", "") & IF(C212!$C$8=G$3,C212!$B$1 & " ", "") & IF(C311!$C$8=G$3,C311!$B$1 & " ", "") & IF(C312!$C$8=G$3,C312!$B$1 & " ", "") & IF(C411!$C$8=G$3,C411!$B$1 & " ", "") & IF(C412!$C$8=G$3,C412!$B$1 & " ", "") & IF(M111!$C$8=G$3,M111!$B$1 & " ", "") & IF(M211!$C$8=G$3,M211!$B$1 & " ", "") & IF(M311!$C$8=G$3,M311!$B$1 & " ", "") & IF(M411!$C$8=G$3,M411!$B$1 & " ", ""))), " ", ",") | H5: =SUBSTITUTE(TRIM((IF(D111!$C$8=H$3,D111!$B$1 & " ", "") & IF(D211!$C$8=H$3,D211!$B$1 & " ", "") & IF(D311!$C$8=H$3,D311!$B$1 & " ", "") & IF(D411!$C$8=H$3,D411!$B$1 & " ", "") & IF(C111!$C$8=H$3,C111!$B$1 & " ", "") & IF(C121!$C$8=H$3,C121!$B$1 & " ", "") & IF(C122!$C$8=H$3,C122!$B$1 & " ", "") & IF(C211!$C$8=H$3,C211!$B$1 & " ", "") & IF(C212!$C$8=H$3,C212!$B$1 & " ", "") & IF(C311!$C$8=H$3,C311!$B$1 & " ", "") & IF(C312!$C$8=H$3,C312!$B$1 & " ", "") & IF(C411!$C$8=H$3,C411!$B$1 & " ", "") & IF(C412!$C$8=H$3,C412!$B$1 & " ", "") & IF(M111!$C$8=H$3,M111!$B$1 & " ", "") & IF(M211!$C$8=H$3,M211!$B$1 & " ", "") & IF(M311!$C$8=H$3,M311!$B$1 & " ", "") & IF(M411!$C$8=H$3,M411!$B$1 & " ", ""))), " ", ",") | I5: =SUBSTITUTE(TRIM((IF(D111!$C$8=I$3,D111!$B$1 & " ", "") & IF(D211!$C$8=I$3,D211!$B$1 & " ", "") & IF(D311!$C$8=I$3,D311!$B$1 & " ", "") & IF(D411!$C$8=I$3,D411!$B$1 & " ", "") & IF(C111!$C$8=I$3,C111!$B$1 & " ", "") & IF(C121!$C$8=I$3,C121!$B$1 & " ", "") & IF(C122!$C$8=I$3,C122!$B$1 & " ", "") & IF(C211!$C$8=I$3,C211!$B$1 & " ", "") & IF(C212!$C$8=I$3,C212!$B$1 & " ", "") & IF(C311!$C$8=I$3,C311!$B$1 & " ", "") & IF(C312!$C$8=I$3,C312!$B$1 & " ", "") & IF(C411!$C$8=I$3,C411!$B$1 & " ", "") & IF(C412!$C$8=I$3,C412!$B$1 & " ", "") & IF(M111!$C$8=I$3,M111!$B$1 & " ", "") & IF(M211!$C$8=I$3,M211!$B$1 & " ", "") & IF(M311!$C$8=I$3,M311!$B$1 & " ", "") & IF(M411!$C$8=I$3,M411!$B$1 & " ", ""))), " ", ",") | J5: =SUBSTITUTE(TRIM((IF(D111!$C$8=J$3,D111!$B$1 & " ", "") & IF(D211!$C$8=J$3,D211!$B$1 & " ", "") & IF(D311!$C$8=J$3,D311!$B$1 & " ", "") & IF(D411!$C$8=J$3,D411!$B$1 & " ", "") & IF(C111!$C$8=J$3,C111!$B$1 & " ", "") & IF(C121!$C$8=J$3,C121!$B$1 & " ", "") & IF(C122!$C$8=J$3,C122!$B$1 & " ", "") & IF(C211!$C$8=J$3,C211!$B$1 & " ", "") & IF(C212!$C$8=J$3,C212!$B$1 & " ", "") & IF(C311!$C$8=J$3,C311!$B$1 & " ", "") & IF(C312!$C$8=J$3,C312!$B$1 & " ", "") & IF(C411!$C$8=J$3,C411!$B$1 & " ", "") & IF(C412!$C$8=J$3,C412!$B$1 & " ", "") & IF(M111!$C$8=J$3,M111!$B$1 & " ", "") & IF(M211!$C$8=J$3,M211!$B$1 & " ", "") & IF(M311!$C$8=J$3,M311!$B$1 & " ", "") & IF(M411!$C$8=J$3,M411!$B$1 & " ", ""))), " ", ",") | ... L5: =SUBSTITUTE(TRIM((IF(D111!$C$8=L$3,D111!$B$1 & " ", "") & IF(D211!$C$8=L$3,D211!$B$1 & " ", "") & IF(D311!$C$8=L$3,D311!$B$1 & " ", "") & IF(D411!$C$8=L$3,D411!$B$1 & " ", "") & IF(C111!$C$8=L$3,C111!$B$1 & " ", "") & IF(C121!$C$8=L$3,C121!$B$1 & " ", "") & IF(C122!$C$8=L$3,C122!$B$1 & " ", "") & IF(C211!$C$8=L$3,C211!$B$1 & " ", "") & IF(C212!$C$8=L$3,C212!$B$1 & " ", "") & IF(C311!$C$8=L$3,C311!$B$1 & " ", "") & IF(C312!$C$8=L$3,C312!$B$1 & " ", "") & IF(C411!$C$8=L$3,C411!$B$1 & " ", "") & IF(C412!$C$8=L$3,C412!$B$1 & " ", "") & IF(M111!$C$8=L$3,M111!$B$1 & " ", "") & IF(M211!$C$8=L$3,M211!$B$1 & " ", "") & IF(M311!$C$8=L$3,M311!$B$1 & " ", "") & IF(M411!$C$8=L$3,M411!$B$1 & " ", ""))), " ", ",")
B6: 3ro | C6: =SUBSTITUTE(TRIM((IF(D111!$C$11=C$3,D111!$B$1 & " ", "") & IF(D211!$C$11=C$3,D211!$B$1 & " ", "") & IF(D311!$C$11=C$3,D311!$B$1 & " ", "") & IF(D411!$C$11=C$3,D411!$B$1 & " ", "") & IF(C111!$C$11=C$3,C111!$B$1 & " ", "") & IF(C121!$C$11=C$3,C121!$B$1 & " ", "") & IF(C122!$C$11=C$3,C122!$B$1 & " ", "") & IF(C211!$C$11=C$3,C211!$B$1 & " ", "") & IF(C212!$C$11=C$3,C212!$B$1 & " ", "") & IF(C311!$C$11=C$3,C311!$B$1 & " ", "") & IF(C312!$C$11=C$3,C312!$B$1 & " ", "") & IF(C411!$C$11=C$3,C411!$B$1 & " ", "") & IF(C412!$C$11=C$3,C412!$B$1 & " ", "") & IF(M111!$C$11=C$3,M111!$B$1 & " ", "") & IF(M211!$C$11=C$3,M211!$B$1 & " ", "") & IF(M311!$C$11=C$3,M311!$B$1 & " ", "") & IF(M411!$C$11=C$3,M411!$B$1 & " ", ""))), " ", ",") | D6: =SUBSTITUTE(TRIM((IF(D111!$C$11=D$3,D111!$B$1 & " ", "") & IF(D211!$C$11=D$3,D211!$B$1 & " ", "") & IF(D311!$C$11=D$3,D311!$B$1 & " ", "") & IF(D411!$C$11=D$3,D411!$B$1 & " ", "") & IF(C111!$C$11=D$3,C111!$B$1 & " ", "") & IF(C121!$C$11=D$3,C121!$B$1 & " ", "") & IF(C122!$C$11=D$3,C122!$B$1 & " ", "") & IF(C211!$C$11=D$3,C211!$B$1 & " ", "") & IF(C212!$C$11=D$3,C212!$B$1 & " ", "") & IF(C311!$C$11=D$3,C311!$B$1 & " ", "") & IF(C312!$C$11=D$3,C312!$B$1 & " ", "") & IF(C411!$C$11=D$3,C411!$B$1 & " ", "") & IF(C412!$C$11=D$3,C412!$B$1 & " ", "") & IF(M111!$C$11=D$3,M111!$B$1 & " ", "") & IF(M211!$C$11=D$3,M211!$B$1 & " ", "") & IF(M311!$C$11=D$3,M311!$B$1 & " ", "") & IF(M411!$C$11=D$3,M411!$B$1 & " ", ""))), " ", ",") | E6: =SUBSTITUTE(TRIM((IF(D111!$C$11=E$3,D111!$B$1 & " ", "") & IF(D211!$C$11=E$3,D211!$B$1 & " ", "") & IF(D311!$C$11=E$3,D311!$B$1 & " ", "") & IF(D411!$C$11=E$3,D411!$B$1 & " ", "") & IF(C111!$C$11=E$3,C111!$B$1 & " ", "") & IF(C121!$C$11=E$3,C121!$B$1 & " ", "") & IF(C122!$C$11=E$3,C122!$B$1 & " ", "") & IF(C211!$C$11=E$3,C211!$B$1 & " ", "") & IF(C212!$C$11=E$3,C212!$B$1 & " ", "") & IF(C311!$C$11=E$3,C311!$B$1 & " ", "") & IF(C312!$C$11=E$3,C312!$B$1 & " ", "") & IF(C411!$C$11=E$3,C411!$B$1 & " ", "") & IF(C412!$C$11=E$3,C412!$B$1 & " ", "") & IF(M111!$C$11=E$3,M111!$B$1 & " ", "") & IF(M211!$C$11=E$3,M211!$B$1 & " ", "") & IF(M311!$C$11=E$3,M311!$B$1 & " ", "") & IF(M411!$C$11=E$3,M411!$B$1 & " ", ""))), " ", ",") | F6: =SUBSTITUTE(TRIM((IF(D111!$C$11=F$3,D111!$B$1 & " ", "") & IF(D211!$C$11=F$3,D211!$B$1 & " ", "") & IF(D311!$C$11=F$3,D311!$B$1 & " ", "") & IF(D411!$C$11=F$3,D411!$B$1 & " ", "") & IF(C111!$C$11=F$3,C111!$B$1 & " ", "") & IF(C121!$C$11=F$3,C121!$B$1 & " ", "") & IF(C122!$C$11=F$3,C122!$B$1 & " ", "") & IF(C211!$C$11=F$3,C211!$B$1 & " ", "") & IF(C212!$C$11=F$3,C212!$B$1 & " ", "") & IF(C311!$C$11=F$3,C311!$B$1 & " ", "") & IF(C312!$C$11=F$3,C312!$B$1 & " ", "") & IF(C411!$C$11=F$3,C411!$B$1 & " ", "") & IF(C412!$C$11=F$3,C412!$B$1 & " ", "") & IF(M111!$C$11=F$3,M111!$B$1 & " ", "") & IF(M211!$C$11=F$3,M211!$B$1 & " ", "") & IF(M311!$C$11=F$3,M311!$B$1 & " ", "") & IF(M411!$C$11=F$3,M411!$B$1 & " ", ""))), " ", ",") | G6: =SUBSTITUTE(TRIM((IF(D111!$C$11=G$3,D111!$B$1 & " ", "") & IF(D211!$C$11=G$3,D211!$B$1 & " ", "") & IF(D311!$C$11=G$3,D311!$B$1 & " ", "") & IF(D411!$C$11=G$3,D411!$B$1 & " ", "") & IF(C111!$C$11=G$3,C111!$B$1 & " ", "") & IF(C121!$C$11=G$3,C121!$B$1 & " ", "") & IF(C122!$C$11=G$3,C122!$B$1 & " ", "") & IF(C211!$C$11=G$3,C211!$B$1 & " ", "") & IF(C212!$C$11=G$3,C212!$B$1 & " ", "") & IF(C311!$C$11=G$3,C311!$B$1 & " ", "") & IF(C312!$C$11=G$3,C312!$B$1 & " ", "") & IF(C411!$C$11=G$3,C411!$B$1 & " ", "") & IF(C412!$C$11=G$3,C412!$B$1 & " ", "") & IF(M111!$C$11=G$3,M111!$B$1 & " ", "") & IF(M211!$C$11=G$3,M211!$B$1 & " ", "") & IF(M311!$C$11=G$3,M311!$B$1 & " ", "") & IF(M411!$C$11=G$3,M411!$B$1 & " ", ""))), " ", ",") | H6: =SUBSTITUTE(TRIM((IF(D111!$C$11=H$3,D111!$B$1 & " ", "") & IF(D211!$C$11=H$3,D211!$B$1 & " ", "") & IF(D311!$C$11=H$3,D311!$B$1 & " ", "") & IF(D411!$C$11=H$3,D411!$B$1 & " ", "") & IF(C111!$C$11=H$3,C111!$B$1 & " ", "") & IF(C121!$C$11=H$3,C121!$B$1 & " ", "") & IF(C122!$C$11=H$3,C122!$B$1 & " ", "") & IF(C211!$C$11=H$3,C211!$B$1 & " ", "") & IF(C212!$C$11=H$3,C212!$B$1 & " ", "") & IF(C311!$C$11=H$3,C311!$B$1 & " ", "") & IF(C312!$C$11=H$3,C312!$B$1 & " ", "") & IF(C411!$C$11=H$3,C411!$B$1 & " ", "") & IF(C412!$C$11=H$3,C412!$B$1 & " ", "") & IF(M111!$C$11=H$3,M111!$B$1 & " ", "") & IF(M211!$C$11=H$3,M211!$B$1 & " ", "") & IF(M311!$C$11=H$3,M311!$B$1 & " ", "") & IF(M411!$C$11=H$3,M411!$B$1 & " ", ""))), " ", ",") | I6: =SUBSTITUTE(TRIM((IF(D111!$C$11=I$3,D111!$B$1 & " ", "") & IF(D211!$C$11=I$3,D211!$B$1 & " ", "") & IF(D311!$C$11=I$3,D311!$B$1 & " ", "") & IF(D411!$C$11=I$3,D411!$B$1 & " ", "") & IF(C111!$C$11=I$3,C111!$B$1 & " ", "") & IF(C121!$C$11=I$3,C121!$B$1 & " ", "") & IF(C122!$C$11=I$3,C122!$B$1 & " ", "") & IF(C211!$C$11=I$3,C211!$B$1 & " ", "") & IF(C212!$C$11=I$3,C212!$B$1 & " ", "") & IF(C311!$C$11=I$3,C311!$B$1 & " ", "") & IF(C312!$C$11=I$3,C312!$B$1 & " ", "") & IF(C411!$C$11=I$3,C411!$B$1 & " ", "") & IF(C412!$C$11=I$3,C412!$B$1 & " ", "") & IF(M111!$C$11=I$3,M111!$B$1 & " ", "") & IF(M211!$C$11=I$3,M211!$B$1 & " ", "") & IF(M311!$C$11=I$3,M311!$B$1 & " ", "") & IF(M411!$C$11=I$3,M411!$B$1 & " ", ""))), " ", ",") | J6: =SUBSTITUTE(TRIM((IF(D111!$C$11=J$3,D111!$B$1 & " ", "") & IF(D211!$C$11=J$3,D211!$B$1 & " ", "") & IF(D311!$C$11=J$3,D311!$B$1 & " ", "") & IF(D411!$C$11=J$3,D411!$B$1 & " ", "") & IF(C111!$C$11=J$3,C111!$B$1 & " ", "") & IF(C121!$C$11=J$3,C121!$B$1 & " ", "") & IF(C122!$C$11=J$3,C122!$B$1 & " ", "") & IF(C211!$C$11=J$3,C211!$B$1 & " ", "") & IF(C212!$C$11=J$3,C212!$B$1 & " ", "") & IF(C311!$C$11=J$3,C311!$B$1 & " ", "") & IF(C312!$C$11=J$3,C312!$B$1 & " ", "") & IF(C411!$C$11=J$3,C411!$B$1 & " ", "") & IF(C412!$C$11=J$3,C412!$B$1 & " ", "") & IF(M111!$C$11=J$3,M111!$B$1 & " ", "") & IF(M211!$C$11=J$3,M211!$B$1 & " ", "") & IF(M311!$C$11=J$3,M311!$B$1 & " ", "") & IF(M411!$C$11=J$3,M411!$B$1 & " ", ""))), " ", ",") | ... L6: =SUBSTITUTE(TRIM((IF(D111!$C$11=L$3,D111!$B$1 & " ", "") & IF(D211!$C$11=L$3,D211!$B$1 & " ", "") & IF(D311!$C$11=L$3,D311!$B$1 & " ", "") & IF(D411!$C$11=L$3,D411!$B$1 & " ", "") & IF(C111!$C$11=L$3,C111!$B$1 & " ", "") & IF(C121!$C$11=L$3,C121!$B$1 & " ", "") & IF(C122!$C$11=L$3,C122!$B$1 & " ", "") & IF(C211!$C$11=L$3,C211!$B$1 & " ", "") & IF(C212!$C$11=L$3,C212!$B$1 & " ", "") & IF(C311!$C$11=L$3,C311!$B$1 & " ", "") & IF(C312!$C$11=L$3,C312!$B$1 & " ", "") & IF(C411!$C$11=L$3,C411!$B$1 & " ", "") & IF(C412!$C$11=L$3,C412!$B$1 & " ", "") & IF(M111!$C$11=L$3,M111!$B$1 & " ", "") & IF(M211!$C$11=L$3,M211!$B$1 & " ", "") & IF(M311!$C$11=L$3,M311!$B$1 & " ", "") & IF(M411!$C$11=L$3,M411!$B$1 & " ", ""))), " ", ",")
B7: 4to | C7: =SUBSTITUTE(TRIM((IF(D111!$C$14=C$3,D111!$B$1 & " ", "") & IF(D211!$C$14=C$3,D211!$B$1 & " ", "") & IF(D311!$C$14=C$3,D311!$B$1 & " ", "") & IF(D411!$C$14=C$3,D411!$B$1 & " ", "") & IF(C111!$C$14=C$3,C111!$B$1 & " ", "") & IF(C121!$C$14=C$3,C121!$B$1 & " ", "") & IF(C122!$C$14=C$3,C122!$B$1 & " ", "") & IF(C211!$C$14=C$3,C211!$B$1 & " ", "") & IF(C212!$C$14=C$3,C212!$B$1 & " ", "") & IF(C311!$C$14=C$3,C311!$B$1 & " ", "") & IF(C312!$C$14=C$3,C312!$B$1 & " ", "") & IF(C411!$C$14=C$3,C411!$B$1 & " ", "") & IF(C412!$C$14=C$3,C412!$B$1 & " ", "") & IF(M111!$C$14=C$3,M111!$B$1 & " ", "") & IF(M211!$C$14=C$3,M211!$B$1 & " ", "") & IF(M311!$C$14=C$3,M311!$B$1 & " ", "") & IF(M411!$C$14=C$3,M411!$B$1 & " ", ""))), " ", ",") | D7: =SUBSTITUTE(TRIM((IF(D111!$C$14=D$3,D111!$B$1 & " ", "") & IF(D211!$C$14=D$3,D211!$B$1 & " ", "") & IF(D311!$C$14=D$3,D311!$B$1 & " ", "") & IF(D411!$C$14=D$3,D411!$B$1 & " ", "") & IF(C111!$C$14=D$3,C111!$B$1 & " ", "") & IF(C121!$C$14=D$3,C121!$B$1 & " ", "") & IF(C122!$C$14=D$3,C122!$B$1 & " ", "") & IF(C211!$C$14=D$3,C211!$B$1 & " ", "") & IF(C212!$C$14=D$3,C212!$B$1 & " ", "") & IF(C311!$C$14=D$3,C311!$B$1 & " ", "") & IF(C312!$C$14=D$3,C312!$B$1 & " ", "") & IF(C411!$C$14=D$3,C411!$B$1 & " ", "") & IF(C412!$C$14=D$3,C412!$B$1 & " ", "") & IF(M111!$C$14=D$3,M111!$B$1 & " ", "") & IF(M211!$C$14=D$3,M211!$B$1 & " ", "") & IF(M311!$C$14=D$3,M311!$B$1 & " ", "") & IF(M411!$C$14=D$3,M411!$B$1 & " ", ""))), " ", ",") | E7: =SUBSTITUTE(TRIM((IF(D111!$C$14=E$3,D111!$B$1 & " ", "") & IF(D211!$C$14=E$3,D211!$B$1 & " ", "") & IF(D311!$C$14=E$3,D311!$B$1 & " ", "") & IF(D411!$C$14=E$3,D411!$B$1 & " ", "") & IF(C111!$C$14=E$3,C111!$B$1 & " ", "") & IF(C121!$C$14=E$3,C121!$B$1 & " ", "") & IF(C122!$C$14=E$3,C122!$B$1 & " ", "") & IF(C211!$C$14=E$3,C211!$B$1 & " ", "") & IF(C212!$C$14=E$3,C212!$B$1 & " ", "") & IF(C311!$C$14=E$3,C311!$B$1 & " ", "") & IF(C312!$C$14=E$3,C312!$B$1 & " ", "") & IF(C411!$C$14=E$3,C411!$B$1 & " ", "") & IF(C412!$C$14=E$3,C412!$B$1 & " ", "") & IF(M111!$C$14=E$3,M111!$B$1 & " ", "") & IF(M211!$C$14=E$3,M211!$B$1 & " ", "") & IF(M311!$C$14=E$3,M311!$B$1 & " ", "") & IF(M411!$C$14=E$3,M411!$B$1 & " ", ""))), " ", ",") | F7: =SUBSTITUTE(TRIM((IF(D111!$C$14=F$3,D111!$B$1 & " ", "") & IF(D211!$C$14=F$3,D211!$B$1 & " ", "") & IF(D311!$C$14=F$3,D311!$B$1 & " ", "") & IF(D411!$C$14=F$3,D411!$B$1 & " ", "") & IF(C111!$C$14=F$3,C111!$B$1 & " ", "") & IF(C121!$C$14=F$3,C121!$B$1 & " ", "") & IF(C122!$C$14=F$3,C122!$B$1 & " ", "") & IF(C211!$C$14=F$3,C211!$B$1 & " ", "") & IF(C212!$C$14=F$3,C212!$B$1 & " ", "") & IF(C311!$C$14=F$3,C311!$B$1 & " ", "") & IF(C312!$C$14=F$3,C312!$B$1 & " ", "") & IF(C411!$C$14=F$3,C411!$B$1 & " ", "") & IF(C412!$C$14=F$3,C412!$B$1 & " ", "") & IF(M111!$C$14=F$3,M111!$B$1 & " ", "") & IF(M211!$C$14=F$3,M211!$B$1 & " ", "") & IF(M311!$C$14=F$3,M311!$B$1 & " ", "") & IF(M411!$C$14=F$3,M411!$B$1 & " ", ""))), " ", ",") | G7: =SUBSTITUTE(TRIM((IF(D111!$C$14=G$3,D111!$B$1 & " ", "") & IF(D211!$C$14=G$3,D211!$B$1 & " ", "") & IF(D311!$C$14=G$3,D311!$B$1 & " ", "") & IF(D411!$C$14=G$3,D411!$B$1 & " ", "") & IF(C111!$C$14=G$3,C111!$B$1 & " ", "") & IF(C121!$C$14=G$3,C121!$B$1 & " ", "") & IF(C122!$C$14=G$3,C122!$B$1 & " ", "") & IF(C211!$C$14=G$3,C211!$B$1 & " ", "") & IF(C212!$C$14=G$3,C212!$B$1 & " ", "") & IF(C311!$C$14=G$3,C311!$B$1 & " ", "") & IF(C312!$C$14=G$3,C312!$B$1 & " ", "") & IF(C411!$C$14=G$3,C411!$B$1 & " ", "") & IF(C412!$C$14=G$3,C412!$B$1 & " ", "") & IF(M111!$C$14=G$3,M111!$B$1 & " ", "") & IF(M211!$C$14=G$3,M211!$B$1 & " ", "") & IF(M311!$C$14=G$3,M311!$B$1 & " ", "") & IF(M411!$C$14=G$3,M411!$B$1 & " ", ""))), " ", ",") | H7: =SUBSTITUTE(TRIM((IF(D111!$C$14=H$3,D111!$B$1 & " ", "") & IF(D211!$C$14=H$3,D211!$B$1 & " ", "") & IF(D311!$C$14=H$3,D311!$B$1 & " ", "") & IF(D411!$C$14=H$3,D411!$B$1 & " ", "") & IF(C111!$C$14=H$3,C111!$B$1 & " ", "") & IF(C121!$C$14=H$3,C121!$B$1 & " ", "") & IF(C122!$C$14=H$3,C122!$B$1 & " ", "") & IF(C211!$C$14=H$3,C211!$B$1 & " ", "") & IF(C212!$C$14=H$3,C212!$B$1 & " ", "") & IF(C311!$C$14=H$3,C311!$B$1 & " ", "") & IF(C312!$C$14=H$3,C312!$B$1 & " ", "") & IF(C411!$C$14=H$3,C411!$B$1 & " ", "") & IF(C412!$C$14=H$3,C412!$B$1 & " ", "") & IF(M111!$C$14=H$3,M111!$B$1 & " ", "") & IF(M211!$C$14=H$3,M211!$B$1 & " ", "") & IF(M311!$C$14=H$3,M311!$B$1 & " ", "") & IF(M411!$C$14=H$3,M411!$B$1 & " ", ""))), " ", ",") | I7: =SUBSTITUTE(TRIM((IF(D111!$C$14=I$3,D111!$B$1 & " ", "") & IF(D211!$C$14=I$3,D211!$B$1 & " ", "") & IF(D311!$C$14=I$3,D311!$B$1 & " ", "") & IF(D411!$C$14=I$3,D411!$B$1 & " ", "") & IF(C111!$C$14=I$3,C111!$B$1 & " ", "") & IF(C121!$C$14=I$3,C121!$B$1 & " ", "") & IF(C122!$C$14=I$3,C122!$B$1 & " ", "") & IF(C211!$C$14=I$3,C211!$B$1 & " ", "") & IF(C212!$C$14=I$3,C212!$B$1 & " ", "") & IF(C311!$C$14=I$3,C311!$B$1 & " ", "") & IF(C312!$C$14=I$3,C312!$B$1 & " ", "") & IF(C411!$C$14=I$3,C411!$B$1 & " ", "") & IF(C412!$C$14=I$3,C412!$B$1 & " ", "") & IF(M111!$C$14=I$3,M111!$B$1 & " ", "") & IF(M211!$C$14=I$3,M211!$B$1 & " ", "") & IF(M311!$C$14=I$3,M311!$B$1 & " ", "") & IF(M411!$C$14=I$3,M411!$B$1 & " ", ""))), " ", ",") | J7: =SUBSTITUTE(TRIM((IF(D111!$C$14=J$3,D111!$B$1 & " ", "") & IF(D211!$C$14=J$3,D211!$B$1 & " ", "") & IF(D311!$C$14=J$3,D311!$B$1 & " ", "") & IF(D411!$C$14=J$3,D411!$B$1 & " ", "") & IF(C111!$C$14=J$3,C111!$B$1 & " ", "") & IF(C121!$C$14=J$3,C121!$B$1 & " ", "") & IF(C122!$C$14=J$3,C122!$B$1 & " ", "") & IF(C211!$C$14=J$3,C211!$B$1 & " ", "") & IF(C212!$C$14=J$3,C212!$B$1 & " ", "") & IF(C311!$C$14=J$3,C311!$B$1 & " ", "") & IF(C312!$C$14=J$3,C312!$B$1 & " ", "") & IF(C411!$C$14=J$3,C411!$B$1 & " ", "") & IF(C412!$C$14=J$3,C412!$B$1 & " ", "") & IF(M111!$C$14=J$3,M111!$B$1 & " ", "") & IF(M211!$C$14=J$3,M211!$B$1 & " ", "") & IF(M311!$C$14=J$3,M311!$B$1 & " ", "") & IF(M411!$C$14=J$3,M411!$B$1 & " ", ""))), " ", ",") | ... L7: =SUBSTITUTE(TRIM((IF(D111!$C$14=L$3,D111!$B$1 & " ", "") & IF(D211!$C$14=L$3,D211!$B$1 & " ", "") & IF(D311!$C$14=L$3,D311!$B$1 & " ", "") & IF(D411!$C$14=L$3,D411!$B$1 & " ", "") & IF(C111!$C$14=L$3,C111!$B$1 & " ", "") & IF(C121!$C$14=L$3,C121!$B$1 & " ", "") & IF(C122!$C$14=L$3,C122!$B$1 & " ", "") & IF(C211!$C$14=L$3,C211!$B$1 & " ", "") & IF(C212!$C$14=L$3,C212!$B$1 & " ", "") & IF(C311!$C$14=L$3,C311!$B$1 & " ", "") & IF(C312!$C$14=L$3,C312!$B$1 & " ", "") & IF(C411!$C$14=L$3,C411!$B$1 & " ", "") & IF(C412!$C$14=L$3,C412!$B$1 & " ", "") & IF(M111!$C$14=L$3,M111!$B$1 & " ", "") & IF(M211!$C$14=L$3,M211!$B$1 & " ", "") & IF(M311!$C$14=L$3,M311!$B$1 & " ", "") & IF(M411!$C$14=L$3,M411!$B$1 & " ", ""))), " ", ",")
B8: 5to | C8: =SUBSTITUTE(TRIM((IF(D111!$C$17=C$3,D111!$B$1 & " ", "") & IF(D211!$C$17=C$3,D211!$B$1 & " ", "") & IF(D311!$C$17=C$3,D311!$B$1 & " ", "") & IF(D411!$C$17=C$3,D411!$B$1 & " ", "") & IF(C111!$C$17=C$3,C111!$B$1 & " ", "") & IF(C121!$C$17=C$3,C121!$B$1 & " ", "") & IF(C122!$C$17=C$3,C122!$B$1 & " ", "") & IF(C211!$C$17=C$3,C211!$B$1 & " ", "") & IF(C212!$C$17=C$3,C212!$B$1 & " ", "") & IF(C311!$C$17=C$3,C311!$B$1 & " ", "") & IF(C312!$C$17=C$3,C312!$B$1 & " ", "") & IF(C411!$C$17=C$3,C411!$B$1 & " ", "") & IF(C412!$C$17=C$3,C412!$B$1 & " ", "") & IF(M111!$C$17=C$3,M111!$B$1 & " ", "") & IF(M211!$C$17=C$3,M211!$B$1 & " ", "") & IF(M311!$C$17=C$3,M311!$B$1 & " ", "") & IF(M411!$C$17=C$3,M411!$B$1 & " ", ""))), " ", ",") | D8: =SUBSTITUTE(TRIM((IF(D111!$C$17=D$3,D111!$B$1 & " ", "") & IF(D211!$C$17=D$3,D211!$B$1 & " ", "") & IF(D311!$C$17=D$3,D311!$B$1 & " ", "") & IF(D411!$C$17=D$3,D411!$B$1 & " ", "") & IF(C111!$C$17=D$3,C111!$B$1 & " ", "") & IF(C121!$C$17=D$3,C121!$B$1 & " ", "") & IF(C122!$C$17=D$3,C122!$B$1 & " ", "") & IF(C211!$C$17=D$3,C211!$B$1 & " ", "") & IF(C212!$C$17=D$3,C212!$B$1 & " ", "") & IF(C311!$C$17=D$3,C311!$B$1 & " ", "") & IF(C312!$C$17=D$3,C312!$B$1 & " ", "") & IF(C411!$C$17=D$3,C411!$B$1 & " ", "") & IF(C412!$C$17=D$3,C412!$B$1 & " ", "") & IF(M111!$C$17=D$3,M111!$B$1 & " ", "") & IF(M211!$C$17=D$3,M211!$B$1 & " ", "") & IF(M311!$C$17=D$3,M311!$B$1 & " ", "") & IF(M411!$C$17=D$3,M411!$B$1 & " ", ""))), " ", ",") | E8: =SUBSTITUTE(TRIM((IF(D111!$C$17=E$3,D111!$B$1 & " ", "") & IF(D211!$C$17=E$3,D211!$B$1 & " ", "") & IF(D311!$C$17=E$3,D311!$B$1 & " ", "") & IF(D411!$C$17=E$3,D411!$B$1 & " ", "") & IF(C111!$C$17=E$3,C111!$B$1 & " ", "") & IF(C121!$C$17=E$3,C121!$B$1 & " ", "") & IF(C122!$C$17=E$3,C122!$B$1 & " ", "") & IF(C211!$C$17=E$3,C211!$B$1 & " ", "") & IF(C212!$C$17=E$3,C212!$B$1 & " ", "") & IF(C311!$C$17=E$3,C311!$B$1 & " ", "") & IF(C312!$C$17=E$3,C312!$B$1 & " ", "") & IF(C411!$C$17=E$3,C411!$B$1 & " ", "") & IF(C412!$C$17=E$3,C412!$B$1 & " ", "") & IF(M111!$C$17=E$3,M111!$B$1 & " ", "") & IF(M211!$C$17=E$3,M211!$B$1 & " ", "") & IF(M311!$C$17=E$3,M311!$B$1 & " ", "") & IF(M411!$C$17=E$3,M411!$B$1 & " ", ""))), " ", ",") | F8: =SUBSTITUTE(TRIM((IF(D111!$C$17=F$3,D111!$B$1 & " ", "") & IF(D211!$C$17=F$3,D211!$B$1 & " ", "") & IF(D311!$C$17=F$3,D311!$B$1 & " ", "") & IF(D411!$C$17=F$3,D411!$B$1 & " ", "") & IF(C111!$C$17=F$3,C111!$B$1 & " ", "") & IF(C121!$C$17=F$3,C121!$B$1 & " ", "") & IF(C122!$C$17=F$3,C122!$B$1 & " ", "") & IF(C211!$C$17=F$3,C211!$B$1 & " ", "") & IF(C212!$C$17=F$3,C212!$B$1 & " ", "") & IF(C311!$C$17=F$3,C311!$B$1 & " ", "") & IF(C312!$C$17=F$3,C312!$B$1 & " ", "") & IF(C411!$C$17=F$3,C411!$B$1 & " ", "") & IF(C412!$C$17=F$3,C412!$B$1 & " ", "") & IF(M111!$C$17=F$3,M111!$B$1 & " ", "") & IF(M211!$C$17=F$3,M211!$B$1 & " ", "") & IF(M311!$C$17=F$3,M311!$B$1 & " ", "") & IF(M411!$C$17=F$3,M411!$B$1 & " ", ""))), " ", ",") | G8: =SUBSTITUTE(TRIM((IF(D111!$C$17=G$3,D111!$B$1 & " ", "") & IF(D211!$C$17=G$3,D211!$B$1 & " ", "") & IF(D311!$C$17=G$3,D311!$B$1 & " ", "") & IF(D411!$C$17=G$3,D411!$B$1 & " ", "") & IF(C111!$C$17=G$3,C111!$B$1 & " ", "") & IF(C121!$C$17=G$3,C121!$B$1 & " ", "") & IF(C122!$C$17=G$3,C122!$B$1 & " ", "") & IF(C211!$C$17=G$3,C211!$B$1 & " ", "") & IF(C212!$C$17=G$3,C212!$B$1 & " ", "") & IF(C311!$C$17=G$3,C311!$B$1 & " ", "") & IF(C312!$C$17=G$3,C312!$B$1 & " ", "") & IF(C411!$C$17=G$3,C411!$B$1 & " ", "") & IF(C412!$C$17=G$3,C412!$B$1 & " ", "") & IF(M111!$C$17=G$3,M111!$B$1 & " ", "") & IF(M211!$C$17=G$3,M211!$B$1 & " ", "") & IF(M311!$C$17=G$3,M311!$B$1 & " ", "") & IF(M411!$C$17=G$3,M411!$B$1 & " ", ""))), " ", ",") | H8: =SUBSTITUTE(TRIM((IF(D111!$C$17=H$3,D111!$B$1 & " ", "") & IF(D211!$C$17=H$3,D211!$B$1 & " ", "") & IF(D311!$C$17=H$3,D311!$B$1 & " ", "") & IF(D411!$C$17=H$3,D411!$B$1 & " ", "") & IF(C111!$C$17=H$3,C111!$B$1 & " ", "") & IF(C121!$C$17=H$3,C121!$B$1 & " ", "") & IF(C122!$C$17=H$3,C122!$B$1 & " ", "") & IF(C211!$C$17=H$3,C211!$B$1 & " ", "") & IF(C212!$C$17=H$3,C212!$B$1 & " ", "") & IF(C311!$C$17=H$3,C311!$B$1 & " ", "") & IF(C312!$C$17=H$3,C312!$B$1 & " ", "") & IF(C411!$C$17=H$3,C411!$B$1 & " ", "") & IF(C412!$C$17=H$3,C412!$B$1 & " ", "") & IF(M111!$C$17=H$3,M111!$B$1 & " ", "") & IF(M211!$C$17=H$3,M211!$B$1 & " ", "") & IF(M311!$C$17=H$3,M311!$B$1 & " ", "") & IF(M411!$C$17=H$3,M411!$B$1 & " ", ""))), " ", ",") | I8: =SUBSTITUTE(TRIM((IF(D111!$C$17=I$3,D111!$B$1 & " ", "") & IF(D211!$C$17=I$3,D211!$B$1 & " ", "") & IF(D311!$C$17=I$3,D311!$B$1 & " ", "") & IF(D411!$C$17=I$3,D411!$B$1 & " ", "") & IF(C111!$C$17=I$3,C111!$B$1 & " ", "") & IF(C121!$C$17=I$3,C121!$B$1 & " ", "") & IF(C122!$C$17=I$3,C122!$B$1 & " ", "") & IF(C211!$C$17=I$3,C211!$B$1 & " ", "") & IF(C212!$C$17=I$3,C212!$B$1 & " ", "") & IF(C311!$C$17=I$3,C311!$B$1 & " ", "") & IF(C312!$C$17=I$3,C312!$B$1 & " ", "") & IF(C411!$C$17=I$3,C411!$B$1 & " ", "") & IF(C412!$C$17=I$3,C412!$B$1 & " ", "") & IF(M111!$C$17=I$3,M111!$B$1 & " ", "") & IF(M211!$C$17=I$3,M211!$B$1 & " ", "") & IF(M311!$C$17=I$3,M311!$B$1 & " ", "") & IF(M411!$C$17=I$3,M411!$B$1 & " ", ""))), " ", ",") | J8: =SUBSTITUTE(TRIM((IF(D111!$C$17=J$3,D111!$B$1 & " ", "") & IF(D211!$C$17=J$3,D211!$B$1 & " ", "") & IF(D311!$C$17=J$3,D311!$B$1 & " ", "") & IF(D411!$C$17=J$3,D411!$B$1 & " ", "") & IF(C111!$C$17=J$3,C111!$B$1 & " ", "") & IF(C121!$C$17=J$3,C121!$B$1 & " ", "") & IF(C122!$C$17=J$3,C122!$B$1 & " ", "") & IF(C211!$C$17=J$3,C211!$B$1 & " ", "") & IF(C212!$C$17=J$3,C212!$B$1 & " ", "") & IF(C311!$C$17=J$3,C311!$B$1 & " ", "") & IF(C312!$C$17=J$3,C312!$B$1 & " ", "") & IF(C411!$C$17=J$3,C411!$B$1 & " ", "") & IF(C412!$C$17=J$3,C412!$B$1 & " ", "") & IF(M111!$C$17=J$3,M111!$B$1 & " ", "") & IF(M211!$C$17=J$3,M211!$B$1 & " ", "") & IF(M311!$C$17=J$3,M311!$B$1 & " ", "") & IF(M411!$C$17=J$3,M411!$B$1 & " ", ""))), " ", ",") | ... L8: =SUBSTITUTE(TRIM((IF(D111!$C$17=L$3,D111!$B$1 & " ", "") & IF(D211!$C$17=L$3,D211!$B$1 & " ", "") & IF(D311!$C$17=L$3,D311!$B$1 & " ", "") & IF(D411!$C$17=L$3,D411!$B$1 & " ", "") & IF(C111!$C$17=L$3,C111!$B$1 & " ", "") & IF(C121!$C$17=L$3,C121!$B$1 & " ", "") & IF(C122!$C$17=L$3,C122!$B$1 & " ", "") & IF(C211!$C$17=L$3,C211!$B$1 & " ", "") & IF(C212!$C$17=L$3,C212!$B$1 & " ", "") & IF(C311!$C$17=L$3,C311!$B$1 & " ", "") & IF(C312!$C$17=L$3,C312!$B$1 & " ", "") & IF(C411!$C$17=L$3,C411!$B$1 & " ", "") & IF(C412!$C$17=L$3,C412!$B$1 & " ", "") & IF(M111!$C$17=L$3,M111!$B$1 & " ", "") & IF(M211!$C$17=L$3,M211!$B$1 & " ", "") & IF(M311!$C$17=L$3,M311!$B$1 & " ", "") & IF(M411!$C$17=L$3,M411!$B$1 & " ", ""))), " ", ",")
